2022-03-09 22:01:58,601 django.utils.autoreload INFO     Watching for file changes with StatReloader
2022-03-09 22:02:44,977 django.utils.autoreload INFO     Watching for file changes with StatReloader
2022-03-09 22:28:00,910 django.utils.autoreload INFO     /user-management-service/apps/manage_user/models.py changed, reloading.
2022-03-09 22:28:01,573 django.utils.autoreload INFO     Watching for file changes with StatReloader
2022-03-09 22:38:38,574 django.utils.autoreload INFO     /user-management-service/user_management/settings/base.py changed, reloading.
2022-03-09 22:38:39,187 django.utils.autoreload INFO     Watching for file changes with StatReloader
2022-03-09 23:26:46,403 django.utils.autoreload INFO     /user-management-service/user_management/settings/base.py changed, reloading.
2022-03-09 23:26:47,359 django.utils.autoreload INFO     Watching for file changes with StatReloader
2022-03-09 23:28:51,867 django.utils.autoreload INFO     /user-management-service/user_management/settings/base.py changed, reloading.
2022-03-09 23:28:52,487 django.utils.autoreload INFO     Watching for file changes with StatReloader
2022-03-09 23:30:31,072 django.utils.autoreload INFO     /user-management-service/apps/manage_user/migrations/0001_initial.py changed, reloading.
2022-03-09 23:30:31,643 django.utils.autoreload INFO     Watching for file changes with StatReloader
2022-03-09 23:31:37,486 django.utils.autoreload INFO     /user-management-service/apps/manage_user/migrations/0001_initial.py changed, reloading.
2022-03-09 23:31:38,074 django.utils.autoreload INFO     Watching for file changes with StatReloader
2022-03-09 23:32:53,735 django.utils.autoreload INFO     Watching for file changes with StatReloader
2022-03-09 23:32:55,318 django.request ERROR    Internal Server Error: /admin/
Traceback (most recent call last):
  File "/usr/local/lib/python3.9/site-packages/django/db/backends/utils.py", line 84, in _execute
    return self.cursor.execute(sql, params)
  File "/usr/local/lib/python3.9/site-packages/django/db/backends/mysql/base.py", line 73, in execute
    return self.cursor.execute(query, args)
  File "/usr/local/lib/python3.9/site-packages/MySQLdb/cursors.py", line 206, in execute
    res = self._query(query)
  File "/usr/local/lib/python3.9/site-packages/MySQLdb/cursors.py", line 319, in _query
    db.query(q)
  File "/usr/local/lib/python3.9/site-packages/MySQLdb/connections.py", line 259, in query
    _mysql.connection.query(self, query)
MySQLdb._exceptions.ProgrammingError: (1146, "Table 'user_management.manage_user_user' doesn't exist")

The above exception was the direct cause of the following exception:

Traceback (most recent call last):
  File "/usr/local/lib/python3.9/site-packages/django/core/handlers/exception.py", line 47, in inner
    response = get_response(request)
  File "/usr/local/lib/python3.9/site-packages/django/core/handlers/base.py", line 179, in _get_response
    response = wrapped_callback(request, *callback_args, **callback_kwargs)
  File "/usr/local/lib/python3.9/site-packages/django/contrib/admin/sites.py", line 251, in wrapper
    return self.admin_view(view, cacheable)(*args, **kwargs)
  File "/usr/local/lib/python3.9/site-packages/django/utils/decorators.py", line 130, in _wrapped_view
    response = view_func(request, *args, **kwargs)
  File "/usr/local/lib/python3.9/site-packages/django/views/decorators/cache.py", line 44, in _wrapped_view_func
    response = view_func(request, *args, **kwargs)
  File "/usr/local/lib/python3.9/site-packages/django/contrib/admin/sites.py", line 222, in inner
    if not self.has_permission(request):
  File "/usr/local/lib/python3.9/site-packages/django/contrib/admin/sites.py", line 196, in has_permission
    return request.user.is_active and request.user.is_staff
  File "/usr/local/lib/python3.9/site-packages/django/utils/functional.py", line 240, in inner
    self._setup()
  File "/usr/local/lib/python3.9/site-packages/django/utils/functional.py", line 376, in _setup
    self._wrapped = self._setupfunc()
  File "/usr/local/lib/python3.9/site-packages/django/contrib/auth/middleware.py", line 23, in <lambda>
    request.user = SimpleLazyObject(lambda: get_user(request))
  File "/usr/local/lib/python3.9/site-packages/django/contrib/auth/middleware.py", line 11, in get_user
    request._cached_user = auth.get_user(request)
  File "/usr/local/lib/python3.9/site-packages/django/contrib/auth/__init__.py", line 181, in get_user
    user = backend.get_user(user_id)
  File "/usr/local/lib/python3.9/site-packages/django/contrib/auth/backends.py", line 157, in get_user
    user = UserModel._default_manager.get(pk=user_id)
  File "/usr/local/lib/python3.9/site-packages/django/db/models/manager.py", line 85, in manager_method
    return getattr(self.get_queryset(), name)(*args, **kwargs)
  File "/usr/local/lib/python3.9/site-packages/django/db/models/query.py", line 425, in get
    num = len(clone)
  File "/usr/local/lib/python3.9/site-packages/django/db/models/query.py", line 269, in __len__
    self._fetch_all()
  File "/usr/local/lib/python3.9/site-packages/django/db/models/query.py", line 1308, in _fetch_all
    self._result_cache = list(self._iterable_class(self))
  File "/usr/local/lib/python3.9/site-packages/django/db/models/query.py", line 53, in __iter__
    results = compiler.execute_sql(chunked_fetch=self.chunked_fetch, chunk_size=self.chunk_size)
  File "/usr/local/lib/python3.9/site-packages/django/db/models/sql/compiler.py", line 1156, in execute_sql
    cursor.execute(sql, params)
  File "/usr/local/lib/python3.9/site-packages/django/db/backends/utils.py", line 98, in execute
    return super().execute(sql, params)
  File "/usr/local/lib/python3.9/site-packages/django/db/backends/utils.py", line 66, in execute
    return self._execute_with_wrappers(sql, params, many=False, executor=self._execute)
  File "/usr/local/lib/python3.9/site-packages/django/db/backends/utils.py", line 75, in _execute_with_wrappers
    return executor(sql, params, many, context)
  File "/usr/local/lib/python3.9/site-packages/django/db/backends/utils.py", line 84, in _execute
    return self.cursor.execute(sql, params)
  File "/usr/local/lib/python3.9/site-packages/django/db/utils.py", line 90, in __exit__
    raise dj_exc_value.with_traceback(traceback) from exc_value
  File "/usr/local/lib/python3.9/site-packages/django/db/backends/utils.py", line 84, in _execute
    return self.cursor.execute(sql, params)
  File "/usr/local/lib/python3.9/site-packages/django/db/backends/mysql/base.py", line 73, in execute
    return self.cursor.execute(query, args)
  File "/usr/local/lib/python3.9/site-packages/MySQLdb/cursors.py", line 206, in execute
    res = self._query(query)
  File "/usr/local/lib/python3.9/site-packages/MySQLdb/cursors.py", line 319, in _query
    db.query(q)
  File "/usr/local/lib/python3.9/site-packages/MySQLdb/connections.py", line 259, in query
    _mysql.connection.query(self, query)
django.db.utils.ProgrammingError: (1146, "Table 'user_management.manage_user_user' doesn't exist")
2022-03-09 23:33:40,449 django.request ERROR    Internal Server Error: /admin/
Traceback (most recent call last):
  File "/usr/local/lib/python3.9/site-packages/django/db/backends/utils.py", line 84, in _execute
    return self.cursor.execute(sql, params)
  File "/usr/local/lib/python3.9/site-packages/django/db/backends/mysql/base.py", line 73, in execute
    return self.cursor.execute(query, args)
  File "/usr/local/lib/python3.9/site-packages/MySQLdb/cursors.py", line 206, in execute
    res = self._query(query)
  File "/usr/local/lib/python3.9/site-packages/MySQLdb/cursors.py", line 319, in _query
    db.query(q)
  File "/usr/local/lib/python3.9/site-packages/MySQLdb/connections.py", line 259, in query
    _mysql.connection.query(self, query)
MySQLdb._exceptions.ProgrammingError: (1146, "Table 'user_management.manage_user_user' doesn't exist")

The above exception was the direct cause of the following exception:

Traceback (most recent call last):
  File "/usr/local/lib/python3.9/site-packages/django/core/handlers/exception.py", line 47, in inner
    response = get_response(request)
  File "/usr/local/lib/python3.9/site-packages/django/core/handlers/base.py", line 179, in _get_response
    response = wrapped_callback(request, *callback_args, **callback_kwargs)
  File "/usr/local/lib/python3.9/site-packages/django/contrib/admin/sites.py", line 251, in wrapper
    return self.admin_view(view, cacheable)(*args, **kwargs)
  File "/usr/local/lib/python3.9/site-packages/django/utils/decorators.py", line 130, in _wrapped_view
    response = view_func(request, *args, **kwargs)
  File "/usr/local/lib/python3.9/site-packages/django/views/decorators/cache.py", line 44, in _wrapped_view_func
    response = view_func(request, *args, **kwargs)
  File "/usr/local/lib/python3.9/site-packages/django/contrib/admin/sites.py", line 222, in inner
    if not self.has_permission(request):
  File "/usr/local/lib/python3.9/site-packages/django/contrib/admin/sites.py", line 196, in has_permission
    return request.user.is_active and request.user.is_staff
  File "/usr/local/lib/python3.9/site-packages/django/utils/functional.py", line 240, in inner
    self._setup()
  File "/usr/local/lib/python3.9/site-packages/django/utils/functional.py", line 376, in _setup
    self._wrapped = self._setupfunc()
  File "/usr/local/lib/python3.9/site-packages/django/contrib/auth/middleware.py", line 23, in <lambda>
    request.user = SimpleLazyObject(lambda: get_user(request))
  File "/usr/local/lib/python3.9/site-packages/django/contrib/auth/middleware.py", line 11, in get_user
    request._cached_user = auth.get_user(request)
  File "/usr/local/lib/python3.9/site-packages/django/contrib/auth/__init__.py", line 181, in get_user
    user = backend.get_user(user_id)
  File "/usr/local/lib/python3.9/site-packages/django/contrib/auth/backends.py", line 157, in get_user
    user = UserModel._default_manager.get(pk=user_id)
  File "/usr/local/lib/python3.9/site-packages/django/db/models/manager.py", line 85, in manager_method
    return getattr(self.get_queryset(), name)(*args, **kwargs)
  File "/usr/local/lib/python3.9/site-packages/django/db/models/query.py", line 425, in get
    num = len(clone)
  File "/usr/local/lib/python3.9/site-packages/django/db/models/query.py", line 269, in __len__
    self._fetch_all()
  File "/usr/local/lib/python3.9/site-packages/django/db/models/query.py", line 1308, in _fetch_all
    self._result_cache = list(self._iterable_class(self))
  File "/usr/local/lib/python3.9/site-packages/django/db/models/query.py", line 53, in __iter__
    results = compiler.execute_sql(chunked_fetch=self.chunked_fetch, chunk_size=self.chunk_size)
  File "/usr/local/lib/python3.9/site-packages/django/db/models/sql/compiler.py", line 1156, in execute_sql
    cursor.execute(sql, params)
  File "/usr/local/lib/python3.9/site-packages/django/db/backends/utils.py", line 98, in execute
    return super().execute(sql, params)
  File "/usr/local/lib/python3.9/site-packages/django/db/backends/utils.py", line 66, in execute
    return self._execute_with_wrappers(sql, params, many=False, executor=self._execute)
  File "/usr/local/lib/python3.9/site-packages/django/db/backends/utils.py", line 75, in _execute_with_wrappers
    return executor(sql, params, many, context)
  File "/usr/local/lib/python3.9/site-packages/django/db/backends/utils.py", line 84, in _execute
    return self.cursor.execute(sql, params)
  File "/usr/local/lib/python3.9/site-packages/django/db/utils.py", line 90, in __exit__
    raise dj_exc_value.with_traceback(traceback) from exc_value
  File "/usr/local/lib/python3.9/site-packages/django/db/backends/utils.py", line 84, in _execute
    return self.cursor.execute(sql, params)
  File "/usr/local/lib/python3.9/site-packages/django/db/backends/mysql/base.py", line 73, in execute
    return self.cursor.execute(query, args)
  File "/usr/local/lib/python3.9/site-packages/MySQLdb/cursors.py", line 206, in execute
    res = self._query(query)
  File "/usr/local/lib/python3.9/site-packages/MySQLdb/cursors.py", line 319, in _query
    db.query(q)
  File "/usr/local/lib/python3.9/site-packages/MySQLdb/connections.py", line 259, in query
    _mysql.connection.query(self, query)
django.db.utils.ProgrammingError: (1146, "Table 'user_management.manage_user_user' doesn't exist")
2022-03-09 23:33:41,589 django.request ERROR    Internal Server Error: /admin/
Traceback (most recent call last):
  File "/usr/local/lib/python3.9/site-packages/django/db/backends/utils.py", line 84, in _execute
    return self.cursor.execute(sql, params)
  File "/usr/local/lib/python3.9/site-packages/django/db/backends/mysql/base.py", line 73, in execute
    return self.cursor.execute(query, args)
  File "/usr/local/lib/python3.9/site-packages/MySQLdb/cursors.py", line 206, in execute
    res = self._query(query)
  File "/usr/local/lib/python3.9/site-packages/MySQLdb/cursors.py", line 319, in _query
    db.query(q)
  File "/usr/local/lib/python3.9/site-packages/MySQLdb/connections.py", line 259, in query
    _mysql.connection.query(self, query)
MySQLdb._exceptions.ProgrammingError: (1146, "Table 'user_management.manage_user_user' doesn't exist")

The above exception was the direct cause of the following exception:

Traceback (most recent call last):
  File "/usr/local/lib/python3.9/site-packages/django/core/handlers/exception.py", line 47, in inner
    response = get_response(request)
  File "/usr/local/lib/python3.9/site-packages/django/core/handlers/base.py", line 179, in _get_response
    response = wrapped_callback(request, *callback_args, **callback_kwargs)
  File "/usr/local/lib/python3.9/site-packages/django/contrib/admin/sites.py", line 251, in wrapper
    return self.admin_view(view, cacheable)(*args, **kwargs)
  File "/usr/local/lib/python3.9/site-packages/django/utils/decorators.py", line 130, in _wrapped_view
    response = view_func(request, *args, **kwargs)
  File "/usr/local/lib/python3.9/site-packages/django/views/decorators/cache.py", line 44, in _wrapped_view_func
    response = view_func(request, *args, **kwargs)
  File "/usr/local/lib/python3.9/site-packages/django/contrib/admin/sites.py", line 222, in inner
    if not self.has_permission(request):
  File "/usr/local/lib/python3.9/site-packages/django/contrib/admin/sites.py", line 196, in has_permission
    return request.user.is_active and request.user.is_staff
  File "/usr/local/lib/python3.9/site-packages/django/utils/functional.py", line 240, in inner
    self._setup()
  File "/usr/local/lib/python3.9/site-packages/django/utils/functional.py", line 376, in _setup
    self._wrapped = self._setupfunc()
  File "/usr/local/lib/python3.9/site-packages/django/contrib/auth/middleware.py", line 23, in <lambda>
    request.user = SimpleLazyObject(lambda: get_user(request))
  File "/usr/local/lib/python3.9/site-packages/django/contrib/auth/middleware.py", line 11, in get_user
    request._cached_user = auth.get_user(request)
  File "/usr/local/lib/python3.9/site-packages/django/contrib/auth/__init__.py", line 181, in get_user
    user = backend.get_user(user_id)
  File "/usr/local/lib/python3.9/site-packages/django/contrib/auth/backends.py", line 157, in get_user
    user = UserModel._default_manager.get(pk=user_id)
  File "/usr/local/lib/python3.9/site-packages/django/db/models/manager.py", line 85, in manager_method
    return getattr(self.get_queryset(), name)(*args, **kwargs)
  File "/usr/local/lib/python3.9/site-packages/django/db/models/query.py", line 425, in get
    num = len(clone)
  File "/usr/local/lib/python3.9/site-packages/django/db/models/query.py", line 269, in __len__
    self._fetch_all()
  File "/usr/local/lib/python3.9/site-packages/django/db/models/query.py", line 1308, in _fetch_all
    self._result_cache = list(self._iterable_class(self))
  File "/usr/local/lib/python3.9/site-packages/django/db/models/query.py", line 53, in __iter__
    results = compiler.execute_sql(chunked_fetch=self.chunked_fetch, chunk_size=self.chunk_size)
  File "/usr/local/lib/python3.9/site-packages/django/db/models/sql/compiler.py", line 1156, in execute_sql
    cursor.execute(sql, params)
  File "/usr/local/lib/python3.9/site-packages/django/db/backends/utils.py", line 98, in execute
    return super().execute(sql, params)
  File "/usr/local/lib/python3.9/site-packages/django/db/backends/utils.py", line 66, in execute
    return self._execute_with_wrappers(sql, params, many=False, executor=self._execute)
  File "/usr/local/lib/python3.9/site-packages/django/db/backends/utils.py", line 75, in _execute_with_wrappers
    return executor(sql, params, many, context)
  File "/usr/local/lib/python3.9/site-packages/django/db/backends/utils.py", line 84, in _execute
    return self.cursor.execute(sql, params)
  File "/usr/local/lib/python3.9/site-packages/django/db/utils.py", line 90, in __exit__
    raise dj_exc_value.with_traceback(traceback) from exc_value
  File "/usr/local/lib/python3.9/site-packages/django/db/backends/utils.py", line 84, in _execute
    return self.cursor.execute(sql, params)
  File "/usr/local/lib/python3.9/site-packages/django/db/backends/mysql/base.py", line 73, in execute
    return self.cursor.execute(query, args)
  File "/usr/local/lib/python3.9/site-packages/MySQLdb/cursors.py", line 206, in execute
    res = self._query(query)
  File "/usr/local/lib/python3.9/site-packages/MySQLdb/cursors.py", line 319, in _query
    db.query(q)
  File "/usr/local/lib/python3.9/site-packages/MySQLdb/connections.py", line 259, in query
    _mysql.connection.query(self, query)
django.db.utils.ProgrammingError: (1146, "Table 'user_management.manage_user_user' doesn't exist")
2022-03-09 23:34:24,427 django.utils.autoreload INFO     Watching for file changes with StatReloader
2022-03-09 23:35:32,289 django.utils.autoreload INFO     Watching for file changes with StatReloader
2022-03-09 23:35:37,016 django.request ERROR    Internal Server Error: /admin/
Traceback (most recent call last):
  File "/usr/local/lib/python3.9/site-packages/django/contrib/sessions/backends/base.py", line 233, in _get_session
    return self._session_cache
AttributeError: 'SessionStore' object has no attribute '_session_cache'

During handling of the above exception, another exception occurred:

Traceback (most recent call last):
  File "/usr/local/lib/python3.9/site-packages/django/db/backends/utils.py", line 84, in _execute
    return self.cursor.execute(sql, params)
  File "/usr/local/lib/python3.9/site-packages/django/db/backends/mysql/base.py", line 73, in execute
    return self.cursor.execute(query, args)
  File "/usr/local/lib/python3.9/site-packages/MySQLdb/cursors.py", line 206, in execute
    res = self._query(query)
  File "/usr/local/lib/python3.9/site-packages/MySQLdb/cursors.py", line 319, in _query
    db.query(q)
  File "/usr/local/lib/python3.9/site-packages/MySQLdb/connections.py", line 259, in query
    _mysql.connection.query(self, query)
MySQLdb._exceptions.ProgrammingError: (1146, "Table 'user_management.django_session' doesn't exist")

The above exception was the direct cause of the following exception:

Traceback (most recent call last):
  File "/usr/local/lib/python3.9/site-packages/django/core/handlers/exception.py", line 47, in inner
    response = get_response(request)
  File "/usr/local/lib/python3.9/site-packages/django/core/handlers/base.py", line 179, in _get_response
    response = wrapped_callback(request, *callback_args, **callback_kwargs)
  File "/usr/local/lib/python3.9/site-packages/django/contrib/admin/sites.py", line 251, in wrapper
    return self.admin_view(view, cacheable)(*args, **kwargs)
  File "/usr/local/lib/python3.9/site-packages/django/utils/decorators.py", line 130, in _wrapped_view
    response = view_func(request, *args, **kwargs)
  File "/usr/local/lib/python3.9/site-packages/django/views/decorators/cache.py", line 44, in _wrapped_view_func
    response = view_func(request, *args, **kwargs)
  File "/usr/local/lib/python3.9/site-packages/django/contrib/admin/sites.py", line 222, in inner
    if not self.has_permission(request):
  File "/usr/local/lib/python3.9/site-packages/django/contrib/admin/sites.py", line 196, in has_permission
    return request.user.is_active and request.user.is_staff
  File "/usr/local/lib/python3.9/site-packages/django/utils/functional.py", line 240, in inner
    self._setup()
  File "/usr/local/lib/python3.9/site-packages/django/utils/functional.py", line 376, in _setup
    self._wrapped = self._setupfunc()
  File "/usr/local/lib/python3.9/site-packages/django/contrib/auth/middleware.py", line 23, in <lambda>
    request.user = SimpleLazyObject(lambda: get_user(request))
  File "/usr/local/lib/python3.9/site-packages/django/contrib/auth/middleware.py", line 11, in get_user
    request._cached_user = auth.get_user(request)
  File "/usr/local/lib/python3.9/site-packages/django/contrib/auth/__init__.py", line 174, in get_user
    user_id = _get_user_session_key(request)
  File "/usr/local/lib/python3.9/site-packages/django/contrib/auth/__init__.py", line 58, in _get_user_session_key
    return get_user_model()._meta.pk.to_python(request.session[SESSION_KEY])
  File "/usr/local/lib/python3.9/site-packages/django/contrib/sessions/backends/base.py", line 65, in __getitem__
    return self._session[key]
  File "/usr/local/lib/python3.9/site-packages/django/contrib/sessions/backends/base.py", line 238, in _get_session
    self._session_cache = self.load()
  File "/usr/local/lib/python3.9/site-packages/django/contrib/sessions/backends/db.py", line 43, in load
    s = self._get_session_from_db()
  File "/usr/local/lib/python3.9/site-packages/django/contrib/sessions/backends/db.py", line 32, in _get_session_from_db
    return self.model.objects.get(
  File "/usr/local/lib/python3.9/site-packages/django/db/models/manager.py", line 85, in manager_method
    return getattr(self.get_queryset(), name)(*args, **kwargs)
  File "/usr/local/lib/python3.9/site-packages/django/db/models/query.py", line 425, in get
    num = len(clone)
  File "/usr/local/lib/python3.9/site-packages/django/db/models/query.py", line 269, in __len__
    self._fetch_all()
  File "/usr/local/lib/python3.9/site-packages/django/db/models/query.py", line 1308, in _fetch_all
    self._result_cache = list(self._iterable_class(self))
  File "/usr/local/lib/python3.9/site-packages/django/db/models/query.py", line 53, in __iter__
    results = compiler.execute_sql(chunked_fetch=self.chunked_fetch, chunk_size=self.chunk_size)
  File "/usr/local/lib/python3.9/site-packages/django/db/models/sql/compiler.py", line 1156, in execute_sql
    cursor.execute(sql, params)
  File "/usr/local/lib/python3.9/site-packages/django/db/backends/utils.py", line 98, in execute
    return super().execute(sql, params)
  File "/usr/local/lib/python3.9/site-packages/django/db/backends/utils.py", line 66, in execute
    return self._execute_with_wrappers(sql, params, many=False, executor=self._execute)
  File "/usr/local/lib/python3.9/site-packages/django/db/backends/utils.py", line 75, in _execute_with_wrappers
    return executor(sql, params, many, context)
  File "/usr/local/lib/python3.9/site-packages/django/db/backends/utils.py", line 84, in _execute
    return self.cursor.execute(sql, params)
  File "/usr/local/lib/python3.9/site-packages/django/db/utils.py", line 90, in __exit__
    raise dj_exc_value.with_traceback(traceback) from exc_value
  File "/usr/local/lib/python3.9/site-packages/django/db/backends/utils.py", line 84, in _execute
    return self.cursor.execute(sql, params)
  File "/usr/local/lib/python3.9/site-packages/django/db/backends/mysql/base.py", line 73, in execute
    return self.cursor.execute(query, args)
  File "/usr/local/lib/python3.9/site-packages/MySQLdb/cursors.py", line 206, in execute
    res = self._query(query)
  File "/usr/local/lib/python3.9/site-packages/MySQLdb/cursors.py", line 319, in _query
    db.query(q)
  File "/usr/local/lib/python3.9/site-packages/MySQLdb/connections.py", line 259, in query
    _mysql.connection.query(self, query)
django.db.utils.ProgrammingError: (1146, "Table 'user_management.django_session' doesn't exist")
2022-03-09 23:48:34,892 django.utils.autoreload INFO     /user-management-service/user_management/settings/base.py changed, reloading.
2022-03-09 23:48:35,583 django.utils.autoreload INFO     Watching for file changes with StatReloader
2022-03-09 23:49:18,100 django.utils.autoreload INFO     /user-management-service/apps/common/models.py changed, reloading.
2022-03-09 23:49:18,790 django.utils.autoreload INFO     Watching for file changes with StatReloader
2022-03-10 01:20:13,966 django.utils.autoreload INFO     /user-management-service/user_management/settings/base.py changed, reloading.
2022-03-10 01:20:15,026 django.utils.autoreload INFO     Watching for file changes with StatReloader
2022-03-10 01:21:16,949 django.utils.autoreload INFO     /user-management-service/apps/profiles/models.py changed, reloading.
2022-03-10 01:21:17,606 django.utils.autoreload INFO     Watching for file changes with StatReloader
2022-03-10 01:21:37,325 django.utils.autoreload INFO     /user-management-service/user_management/settings/base.py changed, reloading.
2022-03-10 01:21:37,750 django.utils.autoreload INFO     Watching for file changes with StatReloader
2022-03-10 01:21:56,208 django.utils.autoreload INFO     /user-management-service/user_management/settings/base.py changed, reloading.
2022-03-10 01:21:56,635 django.utils.autoreload INFO     Watching for file changes with StatReloader
2022-03-10 01:26:54,057 django.utils.autoreload INFO     Watching for file changes with StatReloader
2022-03-10 01:27:19,929 django.utils.autoreload INFO     /user-management-service/user_management/settings/base.py changed, reloading.
2022-03-10 01:27:20,360 django.utils.autoreload INFO     Watching for file changes with StatReloader
2022-03-10 01:28:56,219 django.utils.autoreload INFO     Watching for file changes with StatReloader
2022-03-10 01:31:13,536 django.utils.autoreload INFO     Watching for file changes with StatReloader
2022-03-10 01:32:13,831 django.utils.autoreload INFO     Watching for file changes with StatReloader
2022-03-10 01:34:28,689 django.utils.autoreload INFO     Watching for file changes with StatReloader
2022-03-10 01:34:35,063 django.utils.autoreload INFO     /user-management-service/apps/profiles/models.py changed, reloading.
2022-03-10 01:34:35,684 django.utils.autoreload INFO     Watching for file changes with StatReloader
2022-03-10 01:35:10,008 django.utils.autoreload INFO     /user-management-service/apps/profiles/models.py changed, reloading.
2022-03-10 01:35:10,743 django.utils.autoreload INFO     Watching for file changes with StatReloader
2022-03-10 01:37:11,821 django.utils.autoreload INFO     Watching for file changes with StatReloader
2022-03-10 01:39:07,566 django.utils.autoreload INFO     /user-management-service/apps/profiles/models.py changed, reloading.
2022-03-10 01:39:08,134 django.utils.autoreload INFO     Watching for file changes with StatReloader
2022-03-10 01:39:39,128 django.utils.autoreload INFO     /user-management-service/apps/profiles/models.py changed, reloading.
2022-03-10 01:39:39,796 django.utils.autoreload INFO     Watching for file changes with StatReloader
2022-03-10 01:40:01,316 django.utils.autoreload INFO     /user-management-service/apps/profiles/models.py changed, reloading.
2022-03-10 01:40:02,108 django.utils.autoreload INFO     Watching for file changes with StatReloader
2022-03-10 01:40:33,290 django.utils.autoreload INFO     /user-management-service/apps/profiles/models.py changed, reloading.
2022-03-10 01:40:33,976 django.utils.autoreload INFO     Watching for file changes with StatReloader
2022-03-10 01:40:41,859 django.utils.autoreload INFO     /user-management-service/apps/profiles/models.py changed, reloading.
2022-03-10 01:40:42,637 django.utils.autoreload INFO     Watching for file changes with StatReloader
2022-03-10 01:41:31,829 django.utils.autoreload INFO     /user-management-service/apps/profiles/models.py changed, reloading.
2022-03-10 01:41:32,534 django.utils.autoreload INFO     Watching for file changes with StatReloader
2022-03-10 01:42:52,499 django.utils.autoreload INFO     /user-management-service/apps/profiles/models.py changed, reloading.
2022-03-10 01:42:53,197 django.utils.autoreload INFO     Watching for file changes with StatReloader
2022-03-10 01:46:36,996 django.utils.autoreload INFO     /user-management-service/apps/profiles/models.py changed, reloading.
2022-03-10 01:46:37,621 django.utils.autoreload INFO     Watching for file changes with StatReloader
2022-03-10 01:49:08,642 django.utils.autoreload INFO     /user-management-service/apps/profiles/models.py changed, reloading.
2022-03-10 01:49:09,287 django.utils.autoreload INFO     Watching for file changes with StatReloader
2022-03-10 01:50:02,940 django.utils.autoreload INFO     /user-management-service/apps/profiles/models.py changed, reloading.
2022-03-10 01:50:03,669 django.utils.autoreload INFO     Watching for file changes with StatReloader
2022-03-10 01:50:07,156 django.utils.autoreload INFO     /user-management-service/apps/profiles/models.py changed, reloading.
2022-03-10 01:50:07,874 django.utils.autoreload INFO     Watching for file changes with StatReloader
2022-03-10 01:50:55,593 django.utils.autoreload INFO     /user-management-service/apps/profiles/models.py changed, reloading.
2022-03-10 01:50:56,362 django.utils.autoreload INFO     Watching for file changes with StatReloader
2022-03-10 01:51:39,792 django.utils.autoreload INFO     /user-management-service/apps/profiles/models.py changed, reloading.
2022-03-10 01:51:40,468 django.utils.autoreload INFO     Watching for file changes with StatReloader
2022-03-10 01:51:44,967 django.utils.autoreload INFO     /user-management-service/apps/profiles/models.py changed, reloading.
2022-03-10 01:51:45,687 django.utils.autoreload INFO     Watching for file changes with StatReloader
2022-03-10 01:51:50,328 django.utils.autoreload INFO     /user-management-service/apps/profiles/models.py changed, reloading.
2022-03-10 01:51:51,094 django.utils.autoreload INFO     Watching for file changes with StatReloader
2022-03-10 01:51:53,497 django.utils.autoreload INFO     /user-management-service/apps/profiles/models.py changed, reloading.
2022-03-10 01:51:54,225 django.utils.autoreload INFO     Watching for file changes with StatReloader
2022-03-10 01:51:58,818 django.utils.autoreload INFO     /user-management-service/apps/profiles/models.py changed, reloading.
2022-03-10 01:51:59,500 django.utils.autoreload INFO     Watching for file changes with StatReloader
2022-03-10 01:52:01,978 django.utils.autoreload INFO     /user-management-service/apps/profiles/models.py changed, reloading.
2022-03-10 01:52:02,676 django.utils.autoreload INFO     Watching for file changes with StatReloader
2022-03-10 01:53:02,915 django.utils.autoreload INFO     /user-management-service/apps/profiles/models.py changed, reloading.
2022-03-10 01:53:03,700 django.utils.autoreload INFO     Watching for file changes with StatReloader
2022-03-10 01:53:57,533 django.utils.autoreload INFO     /user-management-service/apps/profiles/models.py changed, reloading.
2022-03-10 01:53:58,291 django.utils.autoreload INFO     Watching for file changes with StatReloader
2022-03-10 01:54:20,082 django.utils.autoreload INFO     /user-management-service/apps/profiles/models.py changed, reloading.
2022-03-10 01:54:20,850 django.utils.autoreload INFO     Watching for file changes with StatReloader
2022-03-10 01:54:36,134 django.utils.autoreload INFO     /user-management-service/apps/profiles/models.py changed, reloading.
2022-03-10 01:54:36,845 django.utils.autoreload INFO     Watching for file changes with StatReloader
2022-03-10 02:03:08,799 django.utils.autoreload INFO     /user-management-service/apps/profiles/admin.py changed, reloading.
2022-03-10 02:03:09,592 django.utils.autoreload INFO     Watching for file changes with StatReloader
2022-03-10 02:03:28,365 django.utils.autoreload INFO     /user-management-service/apps/profiles/admin.py changed, reloading.
2022-03-10 02:03:29,122 django.utils.autoreload INFO     Watching for file changes with StatReloader
2022-03-10 02:03:40,251 django.utils.autoreload INFO     /user-management-service/apps/profiles/admin.py changed, reloading.
2022-03-10 02:03:40,981 django.utils.autoreload INFO     Watching for file changes with StatReloader
2022-03-10 02:05:31,197 django.utils.autoreload INFO     /user-management-service/apps/profiles/models.py changed, reloading.
2022-03-10 02:05:31,909 django.utils.autoreload INFO     Watching for file changes with StatReloader
2022-03-10 02:06:28,606 django.utils.autoreload INFO     /user-management-service/apps/profiles/migrations/0001_initial.py changed, reloading.
2022-03-10 02:06:29,236 django.utils.autoreload INFO     Watching for file changes with StatReloader
2022-03-10 02:09:00,114 django.utils.autoreload INFO     /user-management-service/apps/manage_user/managers.py changed, reloading.
2022-03-10 02:09:00,955 django.utils.autoreload INFO     Watching for file changes with StatReloader
2022-03-10 03:37:26,662 django.utils.autoreload INFO     /user-management-service/user_management/settings/base.py changed, reloading.
2022-03-10 03:37:27,776 django.utils.autoreload INFO     Watching for file changes with StatReloader
2022-03-10 03:37:42,022 django.utils.autoreload INFO     /user-management-service/user_management/settings/base.py changed, reloading.
2022-03-10 03:37:42,695 django.utils.autoreload INFO     Watching for file changes with StatReloader
2022-03-10 03:42:06,653 django.utils.autoreload INFO     /user-management-service/apps/ratings/admin.py changed, reloading.
2022-03-10 03:42:07,441 django.utils.autoreload INFO     Watching for file changes with StatReloader
2022-03-10 04:00:27,978 django.utils.autoreload INFO     Watching for file changes with StatReloader
2022-03-10 04:00:31,814 django.utils.autoreload INFO     /user-management-service/apps/manage_user/serializers.py changed, reloading.
2022-03-10 04:00:32,630 django.utils.autoreload INFO     Watching for file changes with StatReloader
2022-03-10 04:00:35,296 django.utils.autoreload INFO     /user-management-service/apps/manage_user/serializers.py changed, reloading.
2022-03-10 04:00:36,080 django.utils.autoreload INFO     Watching for file changes with StatReloader
2022-03-10 04:01:00,917 django.utils.autoreload INFO     /user-management-service/apps/manage_user/serializers.py changed, reloading.
2022-03-10 04:01:01,819 django.utils.autoreload INFO     Watching for file changes with StatReloader
2022-03-10 04:01:31,855 django.utils.autoreload INFO     /user-management-service/apps/manage_user/serializers.py changed, reloading.
2022-03-10 04:01:32,659 django.utils.autoreload INFO     Watching for file changes with StatReloader
2022-03-10 04:03:44,168 django.utils.autoreload INFO     /user-management-service/apps/manage_user/serializers.py changed, reloading.
2022-03-10 04:03:44,835 django.utils.autoreload INFO     Watching for file changes with StatReloader
2022-03-10 04:03:54,554 django.utils.autoreload INFO     /user-management-service/apps/profiles/models.py changed, reloading.
2022-03-10 04:03:55,416 django.utils.autoreload INFO     Watching for file changes with StatReloader
2022-03-10 04:04:37,093 django.utils.autoreload INFO     /user-management-service/apps/manage_user/serializers.py changed, reloading.
2022-03-10 04:04:37,759 django.utils.autoreload INFO     Watching for file changes with StatReloader
2022-03-10 04:05:05,707 django.utils.autoreload INFO     /user-management-service/apps/manage_user/serializers.py changed, reloading.
2022-03-10 04:05:06,407 django.utils.autoreload INFO     Watching for file changes with StatReloader
2022-03-10 04:06:59,919 django.utils.autoreload INFO     /user-management-service/apps/manage_user/serializers.py changed, reloading.
2022-03-10 04:07:00,762 django.utils.autoreload INFO     Watching for file changes with StatReloader
2022-03-10 04:07:14,023 django.utils.autoreload INFO     /user-management-service/apps/manage_user/serializers.py changed, reloading.
2022-03-10 04:07:14,841 django.utils.autoreload INFO     Watching for file changes with StatReloader
2022-03-10 04:08:20,284 django.utils.autoreload INFO     /user-management-service/apps/manage_user/serializers.py changed, reloading.
2022-03-10 04:08:21,120 django.utils.autoreload INFO     Watching for file changes with StatReloader
2022-03-10 04:10:47,597 django.utils.autoreload INFO     Watching for file changes with StatReloader
2022-03-10 04:11:47,079 django.utils.autoreload INFO     Watching for file changes with StatReloader
2022-03-10 04:12:12,208 django.utils.autoreload INFO     /user-management-service/apps/manage_user/views.py changed, reloading.
2022-03-10 04:12:13,095 django.utils.autoreload INFO     Watching for file changes with StatReloader
2022-03-10 04:12:30,313 django.utils.autoreload INFO     /user-management-service/apps/manage_user/urls.py changed, reloading.
2022-03-10 04:12:31,167 django.utils.autoreload INFO     Watching for file changes with StatReloader
2022-03-10 04:12:46,491 django.utils.autoreload INFO     /user-management-service/apps/manage_user/views.py changed, reloading.
2022-03-10 04:12:47,233 django.utils.autoreload INFO     Watching for file changes with StatReloader
2022-03-10 04:12:59,273 django.utils.autoreload INFO     /user-management-service/apps/manage_user/views.py changed, reloading.
2022-03-10 04:13:00,098 django.utils.autoreload INFO     Watching for file changes with StatReloader
2022-03-10 04:13:14,248 django.utils.autoreload INFO     /user-management-service/apps/manage_user/views.py changed, reloading.
2022-03-10 04:13:14,981 django.utils.autoreload INFO     Watching for file changes with StatReloader
2022-03-10 04:13:23,887 django.utils.autoreload INFO     /user-management-service/apps/manage_user/views.py changed, reloading.
2022-03-10 04:13:24,560 django.utils.autoreload INFO     Watching for file changes with StatReloader
2022-03-10 04:13:53,477 django.utils.autoreload INFO     /user-management-service/apps/manage_user/views.py changed, reloading.
2022-03-10 04:13:54,263 django.utils.autoreload INFO     Watching for file changes with StatReloader
2022-03-10 04:14:20,148 django.utils.autoreload INFO     /user-management-service/apps/manage_user/urls.py changed, reloading.
2022-03-10 04:14:20,954 django.utils.autoreload INFO     Watching for file changes with StatReloader
2022-03-10 04:14:29,883 django.utils.autoreload INFO     /user-management-service/apps/manage_user/urls.py changed, reloading.
2022-03-10 04:14:30,739 django.utils.autoreload INFO     Watching for file changes with StatReloader
2022-03-10 04:16:10,155 django.utils.autoreload INFO     Watching for file changes with StatReloader
2022-03-10 04:23:09,832 django.utils.autoreload INFO     /user-management-service/user_management/settings/base.py changed, reloading.
2022-03-10 04:25:43,270 django.utils.autoreload INFO     Watching for file changes with StatReloader
2022-03-10 17:14:33,819 django.utils.autoreload INFO     Watching for file changes with StatReloader
2022-03-10 17:19:58,500 django.utils.autoreload INFO     /user-management-service/user_management/settings/base.py changed, reloading.
2022-03-10 17:19:59,384 django.utils.autoreload INFO     Watching for file changes with StatReloader
2022-03-10 17:22:30,013 django.request WARNING  Not Found: /api/auth/users/
2022-03-10 17:23:45,425 django.request WARNING  Not Found: /favicon.ico
2022-03-10 17:24:28,220 django.request WARNING  Not Found: /activate/Mg/b22yyh-97ecc29f54cf3b00c22495adb81e2b4b
2022-03-10 17:24:41,056 django.request WARNING  Not Found: /activate/Mg/b22yyh-97ecc29f54cf3b00c22495adb81e2b4b
2022-03-10 17:27:55,730 django.request WARNING  Bad Request: /api/v1/auth/users/activation/
2022-03-10 18:39:22,828 django.request WARNING  Not Found: /api/auth/users/reset_password/
2022-03-10 18:40:27,508 django.request WARNING  Not Found: /password/reset/confirm/Mg/b232in-09c59f06e08d2a435d8ff637f5c3be8d
2022-03-10 19:06:13,625 django.utils.autoreload INFO     /user-management-service/apps/profiles/models.py changed, reloading.
2022-03-10 19:06:14,785 django.utils.autoreload INFO     Watching for file changes with StatReloader
2022-03-10 19:06:41,234 django.utils.autoreload INFO     /user-management-service/apps/profiles/models.py changed, reloading.
2022-03-10 19:06:42,077 django.utils.autoreload INFO     Watching for file changes with StatReloader
2022-03-10 20:03:53,888 django.utils.autoreload INFO     /user-management-service/user_management/urls.py changed, reloading.
2022-03-10 20:03:55,707 django.utils.autoreload INFO     Watching for file changes with StatReloader
2022-03-10 20:04:12,033 django.utils.autoreload INFO     /user-management-service/user_management/urls.py changed, reloading.
2022-03-10 20:04:13,475 django.utils.autoreload INFO     Watching for file changes with StatReloader
2022-03-10 20:04:16,006 django.utils.autoreload INFO     /user-management-service/user_management/urls.py changed, reloading.
2022-03-10 20:04:17,234 django.utils.autoreload INFO     Watching for file changes with StatReloader
2022-03-10 20:06:12,177 django.request WARNING  Unauthorized: /api/v1/auth/jwt/create/
2022-03-10 20:08:39,988 django.request WARNING  Unauthorized: /api/v1/profile/me/
2022-03-10 20:09:04,518 django.utils.autoreload INFO     /user-management-service/apps/profiles/urls.py changed, reloading.
2022-03-10 20:09:05,725 django.utils.autoreload INFO     Watching for file changes with StatReloader
2022-03-10 20:10:25,542 django.utils.autoreload INFO     Watching for file changes with StatReloader
2022-03-10 20:10:35,244 django.request WARNING  Unauthorized: /api/v1/profile/me/
2022-03-10 20:10:59,863 django.request WARNING  Unauthorized: /api/v1/profile/me/
2022-03-10 20:12:43,696 django.request WARNING  Unauthorized: /api/v1/profile/me/
2022-03-10 20:14:10,563 django.utils.autoreload INFO     /user-management-service/user_management/settings/base.py changed, reloading.
2022-03-10 20:14:11,640 django.utils.autoreload INFO     Watching for file changes with StatReloader
2022-03-10 20:14:14,729 django.utils.autoreload INFO     /user-management-service/user_management/settings/base.py changed, reloading.
2022-03-10 20:14:15,738 django.utils.autoreload INFO     Watching for file changes with StatReloader
2022-03-10 20:14:21,642 django.request WARNING  Unauthorized: /api/v1/profile/me/
2022-03-10 20:14:37,639 django.utils.autoreload INFO     /user-management-service/user_management/settings/base.py changed, reloading.
2022-03-10 20:14:38,672 django.utils.autoreload INFO     Watching for file changes with StatReloader
2022-03-10 20:14:48,878 django.request WARNING  Unauthorized: /api/v1/profile/me/
2022-03-10 20:14:56,035 django.utils.autoreload INFO     /user-management-service/user_management/settings/base.py changed, reloading.
2022-03-10 20:14:57,015 django.utils.autoreload INFO     Watching for file changes with StatReloader
2022-03-10 20:16:25,056 django.request WARNING  Unauthorized: /api/v1/profile/me/
2022-03-10 20:16:40,283 django.request WARNING  Unauthorized: /api/v1/profile/me/
2022-03-10 20:16:46,455 django.request WARNING  Unauthorized: /api/v1/profile/me/
2022-03-10 20:17:19,063 django.utils.autoreload INFO     /user-management-service/user_management/settings/base.py changed, reloading.
2022-03-10 20:17:20,260 django.utils.autoreload INFO     Watching for file changes with StatReloader
2022-03-10 20:17:27,669 django.request ERROR    Internal Server Error: /api/v1/profile/me/
Traceback (most recent call last):
  File "/usr/local/lib/python3.9/site-packages/django/db/backends/utils.py", line 84, in _execute
    return self.cursor.execute(sql, params)
  File "/usr/local/lib/python3.9/site-packages/django/db/backends/mysql/base.py", line 73, in execute
    return self.cursor.execute(query, args)
  File "/usr/local/lib/python3.9/site-packages/MySQLdb/cursors.py", line 206, in execute
    res = self._query(query)
  File "/usr/local/lib/python3.9/site-packages/MySQLdb/cursors.py", line 319, in _query
    db.query(q)
  File "/usr/local/lib/python3.9/site-packages/MySQLdb/connections.py", line 259, in query
    _mysql.connection.query(self, query)
MySQLdb._exceptions.OperationalError: (1054, "Unknown column 'profiles_profile.opponent_user' in 'field list'")

The above exception was the direct cause of the following exception:

Traceback (most recent call last):
  File "/usr/local/lib/python3.9/site-packages/django/core/handlers/exception.py", line 47, in inner
    response = get_response(request)
  File "/usr/local/lib/python3.9/site-packages/django/core/handlers/base.py", line 179, in _get_response
    response = wrapped_callback(request, *callback_args, **callback_kwargs)
  File "/usr/local/lib/python3.9/site-packages/django/views/decorators/csrf.py", line 54, in wrapped_view
    return view_func(*args, **kwargs)
  File "/usr/local/lib/python3.9/site-packages/django/views/generic/base.py", line 70, in view
    return self.dispatch(request, *args, **kwargs)
  File "/usr/local/lib/python3.9/site-packages/rest_framework/views.py", line 509, in dispatch
    response = self.handle_exception(exc)
  File "/usr/local/lib/python3.9/site-packages/rest_framework/views.py", line 469, in handle_exception
    self.raise_uncaught_exception(exc)
  File "/usr/local/lib/python3.9/site-packages/rest_framework/views.py", line 480, in raise_uncaught_exception
    raise exc
  File "/usr/local/lib/python3.9/site-packages/rest_framework/views.py", line 506, in dispatch
    response = handler(request, *args, **kwargs)
  File "/user-management-service/apps/profiles/views.py", line 37, in get
    user_profile = Profile.objects.get(user=user)
  File "/usr/local/lib/python3.9/site-packages/django/db/models/manager.py", line 85, in manager_method
    return getattr(self.get_queryset(), name)(*args, **kwargs)
  File "/usr/local/lib/python3.9/site-packages/django/db/models/query.py", line 425, in get
    num = len(clone)
  File "/usr/local/lib/python3.9/site-packages/django/db/models/query.py", line 269, in __len__
    self._fetch_all()
  File "/usr/local/lib/python3.9/site-packages/django/db/models/query.py", line 1308, in _fetch_all
    self._result_cache = list(self._iterable_class(self))
  File "/usr/local/lib/python3.9/site-packages/django/db/models/query.py", line 53, in __iter__
    results = compiler.execute_sql(chunked_fetch=self.chunked_fetch, chunk_size=self.chunk_size)
  File "/usr/local/lib/python3.9/site-packages/django/db/models/sql/compiler.py", line 1156, in execute_sql
    cursor.execute(sql, params)
  File "/usr/local/lib/python3.9/site-packages/django/db/backends/utils.py", line 98, in execute
    return super().execute(sql, params)
  File "/usr/local/lib/python3.9/site-packages/django/db/backends/utils.py", line 66, in execute
    return self._execute_with_wrappers(sql, params, many=False, executor=self._execute)
  File "/usr/local/lib/python3.9/site-packages/django/db/backends/utils.py", line 75, in _execute_with_wrappers
    return executor(sql, params, many, context)
  File "/usr/local/lib/python3.9/site-packages/django/db/backends/utils.py", line 84, in _execute
    return self.cursor.execute(sql, params)
  File "/usr/local/lib/python3.9/site-packages/django/db/utils.py", line 90, in __exit__
    raise dj_exc_value.with_traceback(traceback) from exc_value
  File "/usr/local/lib/python3.9/site-packages/django/db/backends/utils.py", line 84, in _execute
    return self.cursor.execute(sql, params)
  File "/usr/local/lib/python3.9/site-packages/django/db/backends/mysql/base.py", line 73, in execute
    return self.cursor.execute(query, args)
  File "/usr/local/lib/python3.9/site-packages/MySQLdb/cursors.py", line 206, in execute
    res = self._query(query)
  File "/usr/local/lib/python3.9/site-packages/MySQLdb/cursors.py", line 319, in _query
    db.query(q)
  File "/usr/local/lib/python3.9/site-packages/MySQLdb/connections.py", line 259, in query
    _mysql.connection.query(self, query)
django.db.utils.OperationalError: (1054, "Unknown column 'profiles_profile.opponent_user' in 'field list'")
2022-03-10 20:19:15,691 django.request ERROR    Internal Server Error: /api/v1/profile/me/
Traceback (most recent call last):
  File "/usr/local/lib/python3.9/site-packages/django/core/handlers/exception.py", line 47, in inner
    response = get_response(request)
  File "/usr/local/lib/python3.9/site-packages/django/core/handlers/base.py", line 179, in _get_response
    response = wrapped_callback(request, *callback_args, **callback_kwargs)
  File "/usr/local/lib/python3.9/site-packages/django/views/decorators/csrf.py", line 54, in wrapped_view
    return view_func(*args, **kwargs)
  File "/usr/local/lib/python3.9/site-packages/django/views/generic/base.py", line 70, in view
    return self.dispatch(request, *args, **kwargs)
  File "/usr/local/lib/python3.9/site-packages/rest_framework/views.py", line 509, in dispatch
    response = self.handle_exception(exc)
  File "/usr/local/lib/python3.9/site-packages/rest_framework/views.py", line 469, in handle_exception
    self.raise_uncaught_exception(exc)
  File "/usr/local/lib/python3.9/site-packages/rest_framework/views.py", line 480, in raise_uncaught_exception
    raise exc
  File "/usr/local/lib/python3.9/site-packages/rest_framework/views.py", line 506, in dispatch
    response = handler(request, *args, **kwargs)
  File "/user-management-service/apps/profiles/views.py", line 37, in get
    user_profile = Profile.objects.get(user=user)
  File "/usr/local/lib/python3.9/site-packages/django/db/models/manager.py", line 85, in manager_method
    return getattr(self.get_queryset(), name)(*args, **kwargs)
  File "/usr/local/lib/python3.9/site-packages/django/db/models/query.py", line 429, in get
    raise self.model.DoesNotExist(
apps.profiles.models.Profile.DoesNotExist: Profile matching query does not exist.
2022-03-10 20:23:04,470 django.utils.autoreload INFO     /user-management-service/apps/manage_user/models.py changed, reloading.
2022-03-10 20:23:05,535 django.utils.autoreload INFO     Watching for file changes with StatReloader
2022-03-10 20:24:34,634 django.utils.autoreload INFO     /user-management-service/apps/manage_user/serializers.py changed, reloading.
2022-03-10 20:24:35,652 django.utils.autoreload INFO     Watching for file changes with StatReloader
2022-03-10 20:25:01,374 django.utils.autoreload INFO     /user-management-service/apps/manage_user/serializers.py changed, reloading.
2022-03-10 20:25:02,344 django.utils.autoreload INFO     Watching for file changes with StatReloader
2022-03-10 20:25:34,974 django.utils.autoreload INFO     /user-management-service/apps/manage_user/serializers.py changed, reloading.
2022-03-10 20:25:35,766 django.utils.autoreload INFO     Watching for file changes with StatReloader
2022-03-10 20:25:44,024 django.utils.autoreload INFO     /user-management-service/apps/manage_user/serializers.py changed, reloading.
2022-03-10 20:25:44,871 django.utils.autoreload INFO     Watching for file changes with StatReloader
2022-03-10 20:25:46,714 django.utils.autoreload INFO     /user-management-service/apps/manage_user/serializers.py changed, reloading.
2022-03-10 20:25:47,563 django.utils.autoreload INFO     Watching for file changes with StatReloader
2022-03-10 20:26:40,141 django.utils.autoreload INFO     /user-management-service/apps/manage_user/views.py changed, reloading.
2022-03-10 20:26:41,447 django.utils.autoreload INFO     Watching for file changes with StatReloader
2022-03-10 20:29:20,216 django.utils.autoreload INFO     /user-management-service/apps/profiles/serializers.py changed, reloading.
2022-03-10 20:29:20,977 django.utils.autoreload INFO     Watching for file changes with StatReloader
2022-03-10 20:32:31,254 django.request WARNING  Unauthorized: /api/v1/auth/jwt/create/
2022-03-10 20:32:44,803 django.request WARNING  Unauthorized: /api/v1/auth/jwt/create/
2022-03-10 20:34:22,591 django.utils.autoreload INFO     /user-management-service/apps/manage_user/managers.py changed, reloading.
2022-03-10 20:34:23,743 django.utils.autoreload INFO     Watching for file changes with StatReloader
2022-03-10 20:38:53,018 django.utils.autoreload INFO     /user-management-service/apps/manage_user/models.py changed, reloading.
2022-03-10 20:38:54,463 django.utils.autoreload INFO     Watching for file changes with StatReloader
2022-03-10 20:40:00,229 django.utils.autoreload INFO     /user-management-service/apps/manage_user/models.py changed, reloading.
2022-03-10 20:40:01,182 django.utils.autoreload INFO     Watching for file changes with StatReloader
2022-03-10 20:40:07,729 django.utils.autoreload INFO     /user-management-service/apps/manage_user/managers.py changed, reloading.
2022-03-10 20:40:08,894 django.utils.autoreload INFO     Watching for file changes with StatReloader
2022-03-10 20:40:13,031 django.request WARNING  Bad Request: /api/v1/auth/users/activation/
2022-03-10 20:40:24,221 django.request WARNING  Not Found: /activate/Mw/b237oy-4b22c48226146f1257fdec276094c4cb
2022-03-10 20:41:05,845 django.request WARNING  Unauthorized: /api/v1/auth/jwt/create/
2022-03-10 20:41:29,626 django.request ERROR    Internal Server Error: /api/v1/profile/me/
Traceback (most recent call last):
  File "/usr/local/lib/python3.9/site-packages/django/core/handlers/exception.py", line 47, in inner
    response = get_response(request)
  File "/usr/local/lib/python3.9/site-packages/django/core/handlers/base.py", line 179, in _get_response
    response = wrapped_callback(request, *callback_args, **callback_kwargs)
  File "/usr/local/lib/python3.9/site-packages/django/views/decorators/csrf.py", line 54, in wrapped_view
    return view_func(*args, **kwargs)
  File "/usr/local/lib/python3.9/site-packages/django/views/generic/base.py", line 70, in view
    return self.dispatch(request, *args, **kwargs)
  File "/usr/local/lib/python3.9/site-packages/rest_framework/views.py", line 509, in dispatch
    response = self.handle_exception(exc)
  File "/usr/local/lib/python3.9/site-packages/rest_framework/views.py", line 469, in handle_exception
    self.raise_uncaught_exception(exc)
  File "/usr/local/lib/python3.9/site-packages/rest_framework/views.py", line 480, in raise_uncaught_exception
    raise exc
  File "/usr/local/lib/python3.9/site-packages/rest_framework/views.py", line 506, in dispatch
    response = handler(request, *args, **kwargs)
  File "/user-management-service/apps/profiles/views.py", line 37, in get
    user_profile = Profile.objects.get(user=user)
  File "/usr/local/lib/python3.9/site-packages/django/db/models/manager.py", line 85, in manager_method
    return getattr(self.get_queryset(), name)(*args, **kwargs)
  File "/usr/local/lib/python3.9/site-packages/django/db/models/query.py", line 429, in get
    raise self.model.DoesNotExist(
apps.profiles.models.Profile.DoesNotExist: Profile matching query does not exist.
2022-03-10 20:42:25,156 django.utils.autoreload INFO     /user-management-service/apps/profiles/models.py changed, reloading.
2022-03-10 20:42:26,156 django.utils.autoreload INFO     Watching for file changes with StatReloader
2022-03-10 20:44:31,433 django.utils.autoreload INFO     /user-management-service/apps/profiles/models.py changed, reloading.
2022-03-10 20:44:33,238 django.utils.autoreload INFO     Watching for file changes with StatReloader
2022-03-10 20:45:08,394 django.utils.autoreload INFO     /user-management-service/apps/profiles/models.py changed, reloading.
2022-03-10 20:45:09,567 django.utils.autoreload INFO     Watching for file changes with StatReloader
2022-03-10 20:45:19,145 django.utils.autoreload INFO     /user-management-service/apps/profiles/models.py changed, reloading.
2022-03-10 20:45:20,241 django.utils.autoreload INFO     Watching for file changes with StatReloader
2022-03-10 21:01:21,892 django.utils.autoreload INFO     /user-management-service/user_management/settings/development.py changed, reloading.
2022-03-10 21:01:23,027 django.utils.autoreload INFO     Watching for file changes with StatReloader
2022-03-10 21:04:34,608 django.utils.autoreload INFO     /user-management-service/user_management/settings/development.py changed, reloading.
2022-03-10 21:21:20,082 django.utils.autoreload INFO     Watching for file changes with StatReloader
2022-03-10 21:26:32,613 django.utils.autoreload INFO     Watching for file changes with StatReloader
2022-03-10 21:31:17,915 django.utils.autoreload INFO     Watching for file changes with StatReloader
2022-03-10 21:33:09,577 django.utils.autoreload INFO     Watching for file changes with StatReloader
2022-03-10 21:36:32,641 django.utils.autoreload INFO     Watching for file changes with StatReloader
2022-03-10 21:43:47,576 django.utils.autoreload INFO     Watching for file changes with StatReloader
2022-03-10 21:45:53,407 django.utils.autoreload INFO     Watching for file changes with StatReloader
2022-03-10 21:51:48,443 django.utils.autoreload INFO     Watching for file changes with StatReloader
2022-03-10 21:55:38,963 django.utils.autoreload INFO     Watching for file changes with StatReloader
2022-03-10 22:00:58,569 django.utils.autoreload INFO     Watching for file changes with StatReloader
2022-03-11 00:26:13,183 django.utils.autoreload INFO     Watching for file changes with StatReloader
2022-03-11 00:32:06,930 django.utils.autoreload INFO     Watching for file changes with StatReloader
2022-03-11 00:34:00,879 django.utils.autoreload INFO     Watching for file changes with StatReloader
2022-03-11 00:38:16,544 django.utils.autoreload INFO     Watching for file changes with StatReloader
2022-03-11 00:39:59,588 django.utils.autoreload INFO     Watching for file changes with StatReloader
2022-03-11 00:44:27,479 django.utils.autoreload INFO     Watching for file changes with StatReloader
2022-03-11 00:46:08,263 django.utils.autoreload INFO     Watching for file changes with StatReloader
2022-03-11 00:49:46,295 django.utils.autoreload INFO     /app/user_management/urls.py changed, reloading.
2022-03-11 00:49:47,737 django.utils.autoreload INFO     Watching for file changes with StatReloader
2022-03-11 00:51:49,263 django.utils.autoreload INFO     /app/user_management/settings/base.py changed, reloading.
2022-03-11 00:51:51,429 django.utils.autoreload INFO     Watching for file changes with StatReloader
2022-03-11 00:52:07,398 django.utils.autoreload INFO     /app/user_management/settings/base.py changed, reloading.
2022-03-11 00:52:09,165 django.utils.autoreload INFO     Watching for file changes with StatReloader
2022-03-11 00:52:25,091 django.utils.autoreload INFO     /app/user_management/settings/base.py changed, reloading.
2022-03-11 00:52:26,829 django.utils.autoreload INFO     Watching for file changes with StatReloader
2022-03-11 00:52:37,020 django.utils.autoreload INFO     /app/user_management/settings/base.py changed, reloading.
2022-03-11 00:52:38,799 django.utils.autoreload INFO     Watching for file changes with StatReloader
2022-03-11 00:52:50,288 django.utils.autoreload INFO     /app/user_management/settings/base.py changed, reloading.
2022-03-11 00:52:51,799 django.utils.autoreload INFO     Watching for file changes with StatReloader
2022-03-11 00:53:13,035 django.utils.autoreload INFO     /app/user_management/settings/base.py changed, reloading.
2022-03-11 00:53:14,836 django.utils.autoreload INFO     Watching for file changes with StatReloader
2022-03-11 00:53:47,266 django.utils.autoreload INFO     /app/user_management/settings/base.py changed, reloading.
2022-03-11 00:53:49,349 django.utils.autoreload INFO     Watching for file changes with StatReloader
2022-03-11 00:55:56,526 django.utils.autoreload INFO     Watching for file changes with StatReloader
2022-03-11 00:57:42,922 django.utils.autoreload INFO     Watching for file changes with StatReloader
2022-03-11 01:01:48,285 django.utils.autoreload INFO     Watching for file changes with StatReloader
2022-03-11 01:13:42,877 django.utils.autoreload INFO     Watching for file changes with StatReloader
2022-03-11 01:15:36,365 django.utils.autoreload INFO     Watching for file changes with StatReloader
2022-03-11 01:15:45,260 django.utils.autoreload INFO     Watching for file changes with StatReloader
2022-03-11 01:16:11,440 django.utils.autoreload INFO     Watching for file changes with StatReloader
2022-03-11 01:17:23,571 django.utils.autoreload INFO     Watching for file changes with StatReloader
2022-03-11 01:35:59,293 django.utils.autoreload INFO     Watching for file changes with StatReloader
2022-03-11 01:38:56,727 django.utils.autoreload INFO     Watching for file changes with StatReloader
2022-03-11 01:40:07,718 django.utils.autoreload INFO     Watching for file changes with StatReloader
2022-03-11 01:45:12,433 django.utils.autoreload INFO     Watching for file changes with StatReloader
2022-03-11 01:56:09,926 django.utils.autoreload INFO     Watching for file changes with StatReloader
2022-03-11 01:58:59,004 django.utils.autoreload INFO     /app/user_management/urls.py changed, reloading.
2022-03-11 01:59:00,275 django.utils.autoreload INFO     Watching for file changes with StatReloader
2022-03-11 02:02:10,919 django.utils.autoreload INFO     Watching for file changes with StatReloader
2022-03-11 02:21:59,686 django.utils.autoreload INFO     Watching for file changes with StatReloader
2022-03-11 02:24:24,022 django.utils.autoreload INFO     Watching for file changes with StatReloader
2022-03-11 02:30:19,443 django.utils.autoreload INFO     Watching for file changes with StatReloader
2022-03-11 02:31:06,758 django.security.DisallowedHost ERROR    Invalid HTTP_HOST header: '127.0.0.1:8002'. You may need to add '127.0.0.1' to ALLOWED_HOSTS.
2022-03-11 02:31:06,846 django.request WARNING  Bad Request: /admin
2022-03-11 02:31:07,035 django.security.DisallowedHost ERROR    Invalid HTTP_HOST header: '127.0.0.1:8002'. You may need to add '127.0.0.1' to ALLOWED_HOSTS.
2022-03-11 02:31:07,071 django.request WARNING  Bad Request: /favicon.ico
2022-03-11 02:31:26,167 django.security.DisallowedHost ERROR    Invalid HTTP_HOST header: 'localhost:8002'. You may need to add 'localhost' to ALLOWED_HOSTS.
2022-03-11 02:31:26,201 django.request WARNING  Bad Request: /admin/
2022-03-11 02:31:26,394 django.security.DisallowedHost ERROR    Invalid HTTP_HOST header: 'localhost:8002'. You may need to add 'localhost' to ALLOWED_HOSTS.
2022-03-11 02:31:26,427 django.request WARNING  Bad Request: /favicon.ico
2022-03-11 02:32:24,610 django.utils.autoreload INFO     Watching for file changes with StatReloader
2022-03-11 02:32:28,682 django.request WARNING  Not Found: /favicon.ico
2022-03-11 02:36:33,062 django.request WARNING  Not Found: /activate/Mw/b237oy-4b22c48226146f1257fdec276094c4cb
2022-03-11 02:51:46,881 django.utils.autoreload INFO     /app/apps/profiles/renderers.py changed, reloading.
2022-03-11 02:51:48,345 django.utils.autoreload INFO     Watching for file changes with StatReloader
2022-03-11 02:52:57,306 django.utils.autoreload INFO     /app/apps/profiles/renderers.py changed, reloading.
2022-03-11 02:52:58,717 django.utils.autoreload INFO     Watching for file changes with StatReloader
2022-03-11 02:53:31,392 django.utils.autoreload INFO     /app/apps/profiles/renderers.py changed, reloading.
2022-03-11 02:53:32,859 django.utils.autoreload INFO     Watching for file changes with StatReloader
2022-03-11 02:53:40,447 django.utils.autoreload INFO     /app/apps/profiles/renderers.py changed, reloading.
2022-03-11 02:53:41,701 django.utils.autoreload INFO     Watching for file changes with StatReloader
2022-03-11 02:56:45,922 django.utils.autoreload INFO     /app/apps/profiles/views.py changed, reloading.
2022-03-11 02:56:47,161 django.utils.autoreload INFO     Watching for file changes with StatReloader
2022-03-11 03:54:15,692 django.request WARNING  Not Found: /api/v1/profile/roro/
2022-03-11 03:54:24,020 django.request WARNING  Unauthorized: /api/v1/profile/update/roro/
2022-03-11 03:55:20,618 django.request WARNING  Unauthorized: /api/v1/profile/update/roro/
2022-03-11 03:56:01,129 django.request WARNING  Unauthorized: /api/v1/profile/update/roro/
2022-03-11 03:56:32,832 django.request ERROR    Internal Server Error: /api/v1/profile/update/roro/
Traceback (most recent call last):
  File "/usr/local/lib/python3.10/site-packages/django/core/handlers/exception.py", line 47, in inner
    response = get_response(request)
  File "/usr/local/lib/python3.10/site-packages/django/core/handlers/base.py", line 181, in _get_response
    response = wrapped_callback(request, *callback_args, **callback_kwargs)
  File "/usr/local/lib/python3.10/site-packages/django/views/decorators/csrf.py", line 54, in wrapped_view
    return view_func(*args, **kwargs)
  File "/usr/local/lib/python3.10/site-packages/django/views/generic/base.py", line 70, in view
    return self.dispatch(request, *args, **kwargs)
  File "/usr/local/lib/python3.10/site-packages/rest_framework/views.py", line 509, in dispatch
    response = self.handle_exception(exc)
  File "/usr/local/lib/python3.10/site-packages/rest_framework/views.py", line 469, in handle_exception
    self.raise_uncaught_exception(exc)
  File "/usr/local/lib/python3.10/site-packages/rest_framework/views.py", line 480, in raise_uncaught_exception
    raise exc
  File "/usr/local/lib/python3.10/site-packages/rest_framework/views.py", line 506, in dispatch
    response = handler(request, *args, **kwargs)
  File "/app/apps/profiles/views.py", line 65, in patch
    serializer.save()
  File "/usr/local/lib/python3.10/site-packages/rest_framework/serializers.py", line 177, in save
    assert not self.errors, (
AssertionError: You cannot call `.save()` on a serializer with invalid data.
2022-03-11 04:01:56,285 django.request WARNING  Unauthorized: /api/v1/profile/opponents/all/
2022-03-11 04:02:07,555 django.request WARNING  Unauthorized: /api/v1/profile/opponents/all/
2022-03-11 04:02:27,298 django.request WARNING  Unauthorized: /api/v1/profile/opponents/all/
2022-03-11 04:03:25,011 django.request ERROR    Internal Server Error: /api/v1/profile/update/roro/
Traceback (most recent call last):
  File "/usr/local/lib/python3.10/site-packages/django/core/handlers/exception.py", line 47, in inner
    response = get_response(request)
  File "/usr/local/lib/python3.10/site-packages/django/core/handlers/base.py", line 181, in _get_response
    response = wrapped_callback(request, *callback_args, **callback_kwargs)
  File "/usr/local/lib/python3.10/site-packages/django/views/decorators/csrf.py", line 54, in wrapped_view
    return view_func(*args, **kwargs)
  File "/usr/local/lib/python3.10/site-packages/django/views/generic/base.py", line 70, in view
    return self.dispatch(request, *args, **kwargs)
  File "/usr/local/lib/python3.10/site-packages/rest_framework/views.py", line 509, in dispatch
    response = self.handle_exception(exc)
  File "/usr/local/lib/python3.10/site-packages/rest_framework/views.py", line 469, in handle_exception
    self.raise_uncaught_exception(exc)
  File "/usr/local/lib/python3.10/site-packages/rest_framework/views.py", line 480, in raise_uncaught_exception
    raise exc
  File "/usr/local/lib/python3.10/site-packages/rest_framework/views.py", line 506, in dispatch
    response = handler(request, *args, **kwargs)
  File "/app/apps/profiles/views.py", line 65, in patch
    serializer.save()
  File "/usr/local/lib/python3.10/site-packages/rest_framework/serializers.py", line 177, in save
    assert not self.errors, (
AssertionError: You cannot call `.save()` on a serializer with invalid data.
2022-03-11 04:06:20,846 django.utils.autoreload INFO     /app/apps/profiles/urls.py changed, reloading.
2022-03-11 04:06:22,624 django.utils.autoreload INFO     Watching for file changes with StatReloader
2022-03-11 04:06:28,862 django.utils.autoreload INFO     /app/apps/profiles/urls.py changed, reloading.
2022-03-11 04:06:30,192 django.utils.autoreload INFO     Watching for file changes with StatReloader
2022-03-11 04:06:33,464 django.request ERROR    Internal Server Error: /api/v1/profile/update/roro/
Traceback (most recent call last):
  File "/usr/local/lib/python3.10/site-packages/django/core/handlers/exception.py", line 47, in inner
    response = get_response(request)
  File "/usr/local/lib/python3.10/site-packages/django/core/handlers/base.py", line 181, in _get_response
    response = wrapped_callback(request, *callback_args, **callback_kwargs)
  File "/usr/local/lib/python3.10/site-packages/django/views/decorators/csrf.py", line 54, in wrapped_view
    return view_func(*args, **kwargs)
  File "/usr/local/lib/python3.10/site-packages/django/views/generic/base.py", line 70, in view
    return self.dispatch(request, *args, **kwargs)
  File "/usr/local/lib/python3.10/site-packages/rest_framework/views.py", line 509, in dispatch
    response = self.handle_exception(exc)
  File "/usr/local/lib/python3.10/site-packages/rest_framework/views.py", line 469, in handle_exception
    self.raise_uncaught_exception(exc)
  File "/usr/local/lib/python3.10/site-packages/rest_framework/views.py", line 480, in raise_uncaught_exception
    raise exc
  File "/usr/local/lib/python3.10/site-packages/rest_framework/views.py", line 506, in dispatch
    response = handler(request, *args, **kwargs)
  File "/app/apps/profiles/views.py", line 65, in patch
    serializer.save()
  File "/usr/local/lib/python3.10/site-packages/rest_framework/serializers.py", line 177, in save
    assert not self.errors, (
AssertionError: You cannot call `.save()` on a serializer with invalid data.
2022-03-11 04:08:23,248 django.utils.autoreload INFO     /app/apps/profiles/serializers.py changed, reloading.
2022-03-11 04:08:24,640 django.utils.autoreload INFO     Watching for file changes with StatReloader
2022-03-11 04:08:26,030 django.request WARNING  Unauthorized: /api/v1/profile/update/roro/
2022-03-11 04:08:41,305 django.utils.autoreload INFO     /app/user_management/settings/base.py changed, reloading.
2022-03-11 04:08:42,794 django.utils.autoreload INFO     Watching for file changes with StatReloader
2022-03-11 04:08:55,976 django.request ERROR    Internal Server Error: /api/v1/profile/update/roro/
Traceback (most recent call last):
  File "/usr/local/lib/python3.10/site-packages/django/core/handlers/exception.py", line 47, in inner
    response = get_response(request)
  File "/usr/local/lib/python3.10/site-packages/django/core/handlers/base.py", line 181, in _get_response
    response = wrapped_callback(request, *callback_args, **callback_kwargs)
  File "/usr/local/lib/python3.10/site-packages/django/views/decorators/csrf.py", line 54, in wrapped_view
    return view_func(*args, **kwargs)
  File "/usr/local/lib/python3.10/site-packages/django/views/generic/base.py", line 70, in view
    return self.dispatch(request, *args, **kwargs)
  File "/usr/local/lib/python3.10/site-packages/rest_framework/views.py", line 509, in dispatch
    response = self.handle_exception(exc)
  File "/usr/local/lib/python3.10/site-packages/rest_framework/views.py", line 469, in handle_exception
    self.raise_uncaught_exception(exc)
  File "/usr/local/lib/python3.10/site-packages/rest_framework/views.py", line 480, in raise_uncaught_exception
    raise exc
  File "/usr/local/lib/python3.10/site-packages/rest_framework/views.py", line 506, in dispatch
    response = handler(request, *args, **kwargs)
  File "/app/apps/profiles/views.py", line 65, in patch
    serializer.save()
  File "/usr/local/lib/python3.10/site-packages/rest_framework/serializers.py", line 177, in save
    assert not self.errors, (
AssertionError: You cannot call `.save()` on a serializer with invalid data.
2022-03-11 04:09:04,646 django.utils.autoreload INFO     /app/apps/profiles/serializers.py changed, reloading.
2022-03-11 04:09:06,122 django.utils.autoreload INFO     Watching for file changes with StatReloader
2022-03-11 04:09:08,908 django.request ERROR    Internal Server Error: /api/v1/profile/update/roro/
Traceback (most recent call last):
  File "/usr/local/lib/python3.10/site-packages/django/core/handlers/exception.py", line 47, in inner
    response = get_response(request)
  File "/usr/local/lib/python3.10/site-packages/django/core/handlers/base.py", line 181, in _get_response
    response = wrapped_callback(request, *callback_args, **callback_kwargs)
  File "/usr/local/lib/python3.10/site-packages/django/views/decorators/csrf.py", line 54, in wrapped_view
    return view_func(*args, **kwargs)
  File "/usr/local/lib/python3.10/site-packages/django/views/generic/base.py", line 70, in view
    return self.dispatch(request, *args, **kwargs)
  File "/usr/local/lib/python3.10/site-packages/rest_framework/views.py", line 509, in dispatch
    response = self.handle_exception(exc)
  File "/usr/local/lib/python3.10/site-packages/rest_framework/views.py", line 469, in handle_exception
    self.raise_uncaught_exception(exc)
  File "/usr/local/lib/python3.10/site-packages/rest_framework/views.py", line 480, in raise_uncaught_exception
    raise exc
  File "/usr/local/lib/python3.10/site-packages/rest_framework/views.py", line 506, in dispatch
    response = handler(request, *args, **kwargs)
  File "/app/apps/profiles/views.py", line 65, in patch
    serializer.save()
  File "/usr/local/lib/python3.10/site-packages/rest_framework/serializers.py", line 177, in save
    assert not self.errors, (
AssertionError: You cannot call `.save()` on a serializer with invalid data.
2022-03-11 04:09:15,180 django.utils.autoreload INFO     /app/apps/profiles/serializers.py changed, reloading.
2022-03-11 04:09:16,926 django.utils.autoreload INFO     Watching for file changes with StatReloader
2022-03-11 04:09:31,342 django.utils.autoreload INFO     /app/apps/profiles/serializers.py changed, reloading.
2022-03-11 04:09:32,732 django.utils.autoreload INFO     Watching for file changes with StatReloader
2022-03-11 04:10:53,103 django.request ERROR    Internal Server Error: /api/v1/profile/update/roro/
Traceback (most recent call last):
  File "/usr/local/lib/python3.10/site-packages/django/core/handlers/exception.py", line 47, in inner
    response = get_response(request)
  File "/usr/local/lib/python3.10/site-packages/django/core/handlers/base.py", line 181, in _get_response
    response = wrapped_callback(request, *callback_args, **callback_kwargs)
  File "/usr/local/lib/python3.10/site-packages/django/views/decorators/csrf.py", line 54, in wrapped_view
    return view_func(*args, **kwargs)
  File "/usr/local/lib/python3.10/site-packages/django/views/generic/base.py", line 70, in view
    return self.dispatch(request, *args, **kwargs)
  File "/usr/local/lib/python3.10/site-packages/rest_framework/views.py", line 509, in dispatch
    response = self.handle_exception(exc)
  File "/usr/local/lib/python3.10/site-packages/rest_framework/views.py", line 469, in handle_exception
    self.raise_uncaught_exception(exc)
  File "/usr/local/lib/python3.10/site-packages/rest_framework/views.py", line 480, in raise_uncaught_exception
    raise exc
  File "/usr/local/lib/python3.10/site-packages/rest_framework/views.py", line 506, in dispatch
    response = handler(request, *args, **kwargs)
  File "/app/apps/profiles/views.py", line 65, in patch
    serializer.save()
  File "/usr/local/lib/python3.10/site-packages/rest_framework/serializers.py", line 177, in save
    assert not self.errors, (
AssertionError: You cannot call `.save()` on a serializer with invalid data.
2022-03-11 04:11:46,227 django.request WARNING  Forbidden: /api/v1/profile/update/zico/
2022-03-11 04:11:59,028 django.request WARNING  Unauthorized: /api/v1/auth/jwt/create/
2022-03-11 04:12:51,320 django.request ERROR    Internal Server Error: /api/v1/profile/update/zico/
Traceback (most recent call last):
  File "/usr/local/lib/python3.10/site-packages/django/core/handlers/exception.py", line 47, in inner
    response = get_response(request)
  File "/usr/local/lib/python3.10/site-packages/django/core/handlers/base.py", line 181, in _get_response
    response = wrapped_callback(request, *callback_args, **callback_kwargs)
  File "/usr/local/lib/python3.10/site-packages/django/views/decorators/csrf.py", line 54, in wrapped_view
    return view_func(*args, **kwargs)
  File "/usr/local/lib/python3.10/site-packages/django/views/generic/base.py", line 70, in view
    return self.dispatch(request, *args, **kwargs)
  File "/usr/local/lib/python3.10/site-packages/rest_framework/views.py", line 509, in dispatch
    response = self.handle_exception(exc)
  File "/usr/local/lib/python3.10/site-packages/rest_framework/views.py", line 469, in handle_exception
    self.raise_uncaught_exception(exc)
  File "/usr/local/lib/python3.10/site-packages/rest_framework/views.py", line 480, in raise_uncaught_exception
    raise exc
  File "/usr/local/lib/python3.10/site-packages/rest_framework/views.py", line 506, in dispatch
    response = handler(request, *args, **kwargs)
  File "/app/apps/profiles/views.py", line 65, in patch
    serializer.save()
  File "/usr/local/lib/python3.10/site-packages/rest_framework/serializers.py", line 177, in save
    assert not self.errors, (
AssertionError: You cannot call `.save()` on a serializer with invalid data.
2022-03-11 04:14:06,978 django.request WARNING  Unauthorized: /api/v1/profile/opponents/all/
2022-03-11 04:14:47,772 django.utils.autoreload INFO     /app/apps/profiles/views.py changed, reloading.
2022-03-11 04:14:49,212 django.utils.autoreload INFO     Watching for file changes with StatReloader
2022-03-11 04:15:02,667 django.request ERROR    Internal Server Error: /api/v1/profile/update/zico/
Traceback (most recent call last):
  File "/usr/local/lib/python3.10/site-packages/django/core/handlers/exception.py", line 47, in inner
    response = get_response(request)
  File "/usr/local/lib/python3.10/site-packages/django/core/handlers/base.py", line 181, in _get_response
    response = wrapped_callback(request, *callback_args, **callback_kwargs)
  File "/usr/local/lib/python3.10/site-packages/django/views/decorators/csrf.py", line 54, in wrapped_view
    return view_func(*args, **kwargs)
  File "/usr/local/lib/python3.10/site-packages/django/views/generic/base.py", line 70, in view
    return self.dispatch(request, *args, **kwargs)
  File "/usr/local/lib/python3.10/site-packages/rest_framework/views.py", line 509, in dispatch
    response = self.handle_exception(exc)
  File "/usr/local/lib/python3.10/site-packages/rest_framework/views.py", line 469, in handle_exception
    self.raise_uncaught_exception(exc)
  File "/usr/local/lib/python3.10/site-packages/rest_framework/views.py", line 480, in raise_uncaught_exception
    raise exc
  File "/usr/local/lib/python3.10/site-packages/rest_framework/views.py", line 506, in dispatch
    response = handler(request, *args, **kwargs)
  File "/app/apps/profiles/views.py", line 66, in patch
    serializer.save()
  File "/usr/local/lib/python3.10/site-packages/rest_framework/serializers.py", line 177, in save
    assert not self.errors, (
AssertionError: You cannot call `.save()` on a serializer with invalid data.
2022-03-11 04:15:33,867 django.utils.autoreload INFO     /app/apps/profiles/views.py changed, reloading.
2022-03-11 04:15:35,493 django.utils.autoreload INFO     Watching for file changes with StatReloader
2022-03-11 04:15:41,583 django.request ERROR    Internal Server Error: /api/v1/profile/update/zico/
Traceback (most recent call last):
  File "/usr/local/lib/python3.10/site-packages/django/core/handlers/exception.py", line 47, in inner
    response = get_response(request)
  File "/usr/local/lib/python3.10/site-packages/django/core/handlers/base.py", line 181, in _get_response
    response = wrapped_callback(request, *callback_args, **callback_kwargs)
  File "/usr/local/lib/python3.10/site-packages/django/views/decorators/csrf.py", line 54, in wrapped_view
    return view_func(*args, **kwargs)
  File "/usr/local/lib/python3.10/site-packages/django/views/generic/base.py", line 70, in view
    return self.dispatch(request, *args, **kwargs)
  File "/usr/local/lib/python3.10/site-packages/rest_framework/views.py", line 509, in dispatch
    response = self.handle_exception(exc)
  File "/usr/local/lib/python3.10/site-packages/rest_framework/views.py", line 469, in handle_exception
    self.raise_uncaught_exception(exc)
  File "/usr/local/lib/python3.10/site-packages/rest_framework/views.py", line 480, in raise_uncaught_exception
    raise exc
  File "/usr/local/lib/python3.10/site-packages/rest_framework/views.py", line 506, in dispatch
    response = handler(request, *args, **kwargs)
  File "/app/apps/profiles/views.py", line 67, in patch
    serializer.save()
  File "/usr/local/lib/python3.10/site-packages/rest_framework/serializers.py", line 177, in save
    assert not self.errors, (
AssertionError: You cannot call `.save()` on a serializer with invalid data.
2022-03-11 04:16:11,322 django.utils.autoreload INFO     /app/apps/profiles/views.py changed, reloading.
2022-03-11 04:16:12,824 django.utils.autoreload INFO     Watching for file changes with StatReloader
2022-03-11 04:16:15,155 django.utils.autoreload INFO     /app/apps/profiles/views.py changed, reloading.
2022-03-11 04:16:16,364 django.utils.autoreload INFO     Watching for file changes with StatReloader
2022-03-11 04:16:22,262 django.request ERROR    Internal Server Error: /api/v1/profile/update/zico/
Traceback (most recent call last):
  File "/usr/local/lib/python3.10/site-packages/django/core/handlers/exception.py", line 47, in inner
    response = get_response(request)
  File "/usr/local/lib/python3.10/site-packages/django/core/handlers/base.py", line 181, in _get_response
    response = wrapped_callback(request, *callback_args, **callback_kwargs)
  File "/usr/local/lib/python3.10/site-packages/django/views/decorators/csrf.py", line 54, in wrapped_view
    return view_func(*args, **kwargs)
  File "/usr/local/lib/python3.10/site-packages/django/views/generic/base.py", line 70, in view
    return self.dispatch(request, *args, **kwargs)
  File "/usr/local/lib/python3.10/site-packages/rest_framework/views.py", line 509, in dispatch
    response = self.handle_exception(exc)
  File "/usr/local/lib/python3.10/site-packages/rest_framework/views.py", line 469, in handle_exception
    self.raise_uncaught_exception(exc)
  File "/usr/local/lib/python3.10/site-packages/rest_framework/views.py", line 480, in raise_uncaught_exception
    raise exc
  File "/usr/local/lib/python3.10/site-packages/rest_framework/views.py", line 506, in dispatch
    response = handler(request, *args, **kwargs)
  File "/app/apps/profiles/views.py", line 69, in patch
    serializer.save()
  File "/usr/local/lib/python3.10/site-packages/rest_framework/serializers.py", line 177, in save
    assert not self.errors, (
AssertionError: You cannot call `.save()` on a serializer with invalid data.
2022-03-11 04:17:08,098 django.utils.autoreload INFO     /app/apps/profiles/serializers.py changed, reloading.
2022-03-11 04:17:09,512 django.utils.autoreload INFO     Watching for file changes with StatReloader
2022-03-11 04:39:24,977 django.utils.autoreload INFO     /app/apps/profiles/serializers.py changed, reloading.
2022-03-11 04:39:26,604 django.utils.autoreload INFO     Watching for file changes with StatReloader
2022-03-11 14:26:59,342 django.utils.autoreload INFO     /app/user_management/settings/base.py changed, reloading.
2022-03-11 14:38:21,746 django.utils.autoreload INFO     Watching for file changes with StatReloader
2022-03-11 14:46:18,136 django.utils.autoreload INFO     Watching for file changes with StatReloader
2022-03-11 16:38:56,752 django.utils.autoreload INFO     /app/apps/ratings/models.py changed, reloading.
2022-03-11 16:38:58,428 django.utils.autoreload INFO     Watching for file changes with StatReloader
2022-03-11 17:11:06,842 django.request WARNING  Unauthorized: /api/v1/auth/jwt/create/
2022-03-11 17:14:55,472 django.request WARNING  Not Found: /api/v1/ratings/b3e0e23b-5a58-4b0f-883c-aaf0dcbc9024
2022-03-11 17:15:25,056 django.utils.autoreload INFO     /app/user_management/urls.py changed, reloading.
2022-03-11 17:15:26,588 django.utils.autoreload INFO     Watching for file changes with StatReloader
2022-03-11 17:15:53,416 django.utils.autoreload INFO     /app/user_management/urls.py changed, reloading.
2022-03-11 17:15:54,933 django.utils.autoreload INFO     Watching for file changes with StatReloader
2022-03-11 17:16:21,510 django.utils.autoreload INFO     /app/apps/ratings/urls.py changed, reloading.
2022-03-11 17:16:22,983 django.utils.autoreload INFO     Watching for file changes with StatReloader
2022-03-11 17:16:27,228 django.request ERROR    Internal Server Error: /api/v1/ratings/b3e0e23b-5a58-4b0f-883c-aaf0dcbc9024
Traceback (most recent call last):
  File "/usr/local/lib/python3.10/site-packages/django/core/handlers/exception.py", line 47, in inner
    response = get_response(request)
  File "/usr/local/lib/python3.10/site-packages/django/utils/deprecation.py", line 116, in __call__
    response = self.process_request(request)
  File "/usr/local/lib/python3.10/site-packages/django/middleware/common.py", line 54, in process_request
    path = self.get_full_path_with_slash(request)
  File "/usr/local/lib/python3.10/site-packages/django/middleware/common.py", line 88, in get_full_path_with_slash
    raise RuntimeError(
RuntimeError: You called this URL via POST, but the URL doesn't end in a slash and you have APPEND_SLASH set. Django can't redirect to the slash URL while maintaining POST data. Change your form to point to localhost:8002/api/v1/ratings/b3e0e23b-5a58-4b0f-883c-aaf0dcbc9024/ (note the trailing slash), or set APPEND_SLASH=False in your Django settings.
2022-03-11 17:17:23,156 django.request ERROR    Internal Server Error: /api/v1/ratings/b3e0e23b-5a58-4b0f-883c-aaf0dcbc9024/
Traceback (most recent call last):
  File "/usr/local/lib/python3.10/site-packages/django/core/handlers/exception.py", line 47, in inner
    response = get_response(request)
  File "/usr/local/lib/python3.10/site-packages/django/core/handlers/base.py", line 181, in _get_response
    response = wrapped_callback(request, *callback_args, **callback_kwargs)
  File "/usr/local/lib/python3.10/site-packages/django/views/decorators/csrf.py", line 54, in wrapped_view
    return view_func(*args, **kwargs)
  File "/usr/local/lib/python3.10/site-packages/django/views/generic/base.py", line 70, in view
    return self.dispatch(request, *args, **kwargs)
  File "/usr/local/lib/python3.10/site-packages/rest_framework/views.py", line 509, in dispatch
    response = self.handle_exception(exc)
  File "/usr/local/lib/python3.10/site-packages/rest_framework/views.py", line 469, in handle_exception
    self.raise_uncaught_exception(exc)
  File "/usr/local/lib/python3.10/site-packages/rest_framework/views.py", line 480, in raise_uncaught_exception
    raise exc
  File "/usr/local/lib/python3.10/site-packages/rest_framework/views.py", line 506, in dispatch
    response = handler(request, *args, **kwargs)
  File "/usr/local/lib/python3.10/site-packages/rest_framework/decorators.py", line 50, in handler
    return func(*args, **kwargs)
  File "/app/apps/ratings/views.py", line 16, in create_opponent_review
    opponent_profile = Profile.objects.get(id=profile_id, is_opponent=True)
  File "/usr/local/lib/python3.10/site-packages/django/db/models/manager.py", line 85, in manager_method
    return getattr(self.get_queryset(), name)(*args, **kwargs)
  File "/usr/local/lib/python3.10/site-packages/django/db/models/query.py", line 424, in get
    clone = self._chain() if self.query.combinator else self.filter(*args, **kwargs)
  File "/usr/local/lib/python3.10/site-packages/django/db/models/query.py", line 941, in filter
    return self._filter_or_exclude(False, args, kwargs)
  File "/usr/local/lib/python3.10/site-packages/django/db/models/query.py", line 961, in _filter_or_exclude
    clone._filter_or_exclude_inplace(negate, args, kwargs)
  File "/usr/local/lib/python3.10/site-packages/django/db/models/query.py", line 968, in _filter_or_exclude_inplace
    self._query.add_q(Q(*args, **kwargs))
  File "/usr/local/lib/python3.10/site-packages/django/db/models/sql/query.py", line 1393, in add_q
    clause, _ = self._add_q(q_object, self.used_aliases)
  File "/usr/local/lib/python3.10/site-packages/django/db/models/sql/query.py", line 1412, in _add_q
    child_clause, needed_inner = self.build_filter(
  File "/usr/local/lib/python3.10/site-packages/django/db/models/sql/query.py", line 1286, in build_filter
    lookups, parts, reffed_expression = self.solve_lookup_type(arg)
  File "/usr/local/lib/python3.10/site-packages/django/db/models/sql/query.py", line 1112, in solve_lookup_type
    _, field, _, lookup_parts = self.names_to_path(lookup_splitted, self.get_meta())
  File "/usr/local/lib/python3.10/site-packages/django/db/models/sql/query.py", line 1539, in names_to_path
    raise FieldError("Cannot resolve keyword '%s' into field. "
django.core.exceptions.FieldError: Cannot resolve keyword 'is_opponent' into field. Choices are: about_me, age, city, country, created_at, game_type, gender, id, num_reviews, opponent_review, opponent_user, phone_number, pkid, profile_photo, rating, region, skill_level, updated_at, user, user_id, zip_code
2022-03-11 17:18:40,895 django.utils.autoreload INFO     /app/apps/profiles/models.py changed, reloading.
2022-03-11 17:18:42,243 django.utils.autoreload INFO     Watching for file changes with StatReloader
2022-03-11 17:18:49,843 django.utils.autoreload INFO     /app/apps/profiles/models.py changed, reloading.
2022-03-11 17:18:51,264 django.utils.autoreload INFO     Watching for file changes with StatReloader
2022-03-11 17:19:20,089 django.utils.autoreload INFO     /app/apps/profiles/serializers.py changed, reloading.
2022-03-11 17:19:21,554 django.utils.autoreload INFO     Watching for file changes with StatReloader
2022-03-11 17:20:13,786 django.utils.autoreload INFO     /app/apps/profiles/serializers.py changed, reloading.
2022-03-11 17:20:15,337 django.utils.autoreload INFO     Watching for file changes with StatReloader
2022-03-11 17:20:41,514 django.utils.autoreload INFO     /app/apps/profiles/serializers.py changed, reloading.
2022-03-11 17:20:43,054 django.utils.autoreload INFO     Watching for file changes with StatReloader
2022-03-11 17:22:21,144 django.utils.autoreload INFO     /app/apps/profiles/serializers.py changed, reloading.
2022-03-11 17:22:22,544 django.utils.autoreload INFO     Watching for file changes with StatReloader
2022-03-11 17:30:45,059 django.utils.autoreload INFO     /app/apps/ratings/models.py changed, reloading.
2022-03-11 17:30:46,511 django.utils.autoreload INFO     Watching for file changes with StatReloader
2022-03-11 17:56:36,310 django.utils.autoreload INFO     /app/apps/ratings/migrations/0001_initial.py changed, reloading.
2022-03-11 17:56:37,720 django.utils.autoreload INFO     Watching for file changes with StatReloader
2022-03-11 17:57:17,047 django.request ERROR    Internal Server Error: /api/v1/ratings/b3e0e23b-5a58-4b0f-883c-aaf0dcbc9024/
Traceback (most recent call last):
  File "/usr/local/lib/python3.10/site-packages/django/db/backends/utils.py", line 84, in _execute
    return self.cursor.execute(sql, params)
psycopg2.errors.UndefinedColumn: column profiles_profile.is_opponent does not exist
LINE 1: ...le"."num_reviews", "profiles_profile"."about_me", "profiles_...
                                                             ^


The above exception was the direct cause of the following exception:

Traceback (most recent call last):
  File "/usr/local/lib/python3.10/site-packages/django/core/handlers/exception.py", line 47, in inner
    response = get_response(request)
  File "/usr/local/lib/python3.10/site-packages/django/core/handlers/base.py", line 181, in _get_response
    response = wrapped_callback(request, *callback_args, **callback_kwargs)
  File "/usr/local/lib/python3.10/site-packages/django/views/decorators/csrf.py", line 54, in wrapped_view
    return view_func(*args, **kwargs)
  File "/usr/local/lib/python3.10/site-packages/django/views/generic/base.py", line 70, in view
    return self.dispatch(request, *args, **kwargs)
  File "/usr/local/lib/python3.10/site-packages/rest_framework/views.py", line 509, in dispatch
    response = self.handle_exception(exc)
  File "/usr/local/lib/python3.10/site-packages/rest_framework/views.py", line 469, in handle_exception
    self.raise_uncaught_exception(exc)
  File "/usr/local/lib/python3.10/site-packages/rest_framework/views.py", line 480, in raise_uncaught_exception
    raise exc
  File "/usr/local/lib/python3.10/site-packages/rest_framework/views.py", line 506, in dispatch
    response = handler(request, *args, **kwargs)
  File "/usr/local/lib/python3.10/site-packages/rest_framework/decorators.py", line 50, in handler
    return func(*args, **kwargs)
  File "/app/apps/ratings/views.py", line 16, in create_opponent_review
    opponent_profile = Profile.objects.get(id=profile_id, is_opponent=True)
  File "/usr/local/lib/python3.10/site-packages/django/db/models/manager.py", line 85, in manager_method
    return getattr(self.get_queryset(), name)(*args, **kwargs)
  File "/usr/local/lib/python3.10/site-packages/django/db/models/query.py", line 431, in get
    num = len(clone)
  File "/usr/local/lib/python3.10/site-packages/django/db/models/query.py", line 262, in __len__
    self._fetch_all()
  File "/usr/local/lib/python3.10/site-packages/django/db/models/query.py", line 1324, in _fetch_all
    self._result_cache = list(self._iterable_class(self))
  File "/usr/local/lib/python3.10/site-packages/django/db/models/query.py", line 51, in __iter__
    results = compiler.execute_sql(chunked_fetch=self.chunked_fetch, chunk_size=self.chunk_size)
  File "/usr/local/lib/python3.10/site-packages/django/db/models/sql/compiler.py", line 1175, in execute_sql
    cursor.execute(sql, params)
  File "/usr/local/lib/python3.10/site-packages/django/db/backends/utils.py", line 98, in execute
    return super().execute(sql, params)
  File "/usr/local/lib/python3.10/site-packages/django/db/backends/utils.py", line 66, in execute
    return self._execute_with_wrappers(sql, params, many=False, executor=self._execute)
  File "/usr/local/lib/python3.10/site-packages/django/db/backends/utils.py", line 75, in _execute_with_wrappers
    return executor(sql, params, many, context)
  File "/usr/local/lib/python3.10/site-packages/django/db/backends/utils.py", line 79, in _execute
    with self.db.wrap_database_errors:
  File "/usr/local/lib/python3.10/site-packages/django/db/utils.py", line 90, in __exit__
    raise dj_exc_value.with_traceback(traceback) from exc_value
  File "/usr/local/lib/python3.10/site-packages/django/db/backends/utils.py", line 84, in _execute
    return self.cursor.execute(sql, params)
django.db.utils.ProgrammingError: column profiles_profile.is_opponent does not exist
LINE 1: ...le"."num_reviews", "profiles_profile"."about_me", "profiles_...
                                                             ^

2022-03-11 17:58:01,212 django.request ERROR    Internal Server Error: /admin/profiles/profile/
Traceback (most recent call last):
  File "/usr/local/lib/python3.10/site-packages/django/db/backends/utils.py", line 84, in _execute
    return self.cursor.execute(sql, params)
psycopg2.errors.UndefinedColumn: column profiles_profile.is_opponent does not exist
LINE 1: ...le"."num_reviews", "profiles_profile"."about_me", "profiles_...
                                                             ^


The above exception was the direct cause of the following exception:

Traceback (most recent call last):
  File "/usr/local/lib/python3.10/site-packages/django/core/handlers/exception.py", line 47, in inner
    response = get_response(request)
  File "/usr/local/lib/python3.10/site-packages/django/core/handlers/base.py", line 181, in _get_response
    response = wrapped_callback(request, *callback_args, **callback_kwargs)
  File "/usr/local/lib/python3.10/site-packages/django/contrib/admin/options.py", line 616, in wrapper
    return self.admin_site.admin_view(view)(*args, **kwargs)
  File "/usr/local/lib/python3.10/site-packages/django/utils/decorators.py", line 130, in _wrapped_view
    response = view_func(request, *args, **kwargs)
  File "/usr/local/lib/python3.10/site-packages/django/views/decorators/cache.py", line 44, in _wrapped_view_func
    response = view_func(request, *args, **kwargs)
  File "/usr/local/lib/python3.10/site-packages/django/contrib/admin/sites.py", line 232, in inner
    return view(request, *args, **kwargs)
  File "/usr/local/lib/python3.10/site-packages/django/utils/decorators.py", line 43, in _wrapper
    return bound_method(*args, **kwargs)
  File "/usr/local/lib/python3.10/site-packages/django/utils/decorators.py", line 130, in _wrapped_view
    response = view_func(request, *args, **kwargs)
  File "/usr/local/lib/python3.10/site-packages/django/contrib/admin/options.py", line 1815, in changelist_view
    'selection_note': _('0 of %(cnt)s selected') % {'cnt': len(cl.result_list)},
  File "/usr/local/lib/python3.10/site-packages/django/db/models/query.py", line 262, in __len__
    self._fetch_all()
  File "/usr/local/lib/python3.10/site-packages/django/db/models/query.py", line 1324, in _fetch_all
    self._result_cache = list(self._iterable_class(self))
  File "/usr/local/lib/python3.10/site-packages/django/db/models/query.py", line 51, in __iter__
    results = compiler.execute_sql(chunked_fetch=self.chunked_fetch, chunk_size=self.chunk_size)
  File "/usr/local/lib/python3.10/site-packages/django/db/models/sql/compiler.py", line 1175, in execute_sql
    cursor.execute(sql, params)
  File "/usr/local/lib/python3.10/site-packages/django/db/backends/utils.py", line 98, in execute
    return super().execute(sql, params)
  File "/usr/local/lib/python3.10/site-packages/django/db/backends/utils.py", line 66, in execute
    return self._execute_with_wrappers(sql, params, many=False, executor=self._execute)
  File "/usr/local/lib/python3.10/site-packages/django/db/backends/utils.py", line 75, in _execute_with_wrappers
    return executor(sql, params, many, context)
  File "/usr/local/lib/python3.10/site-packages/django/db/backends/utils.py", line 79, in _execute
    with self.db.wrap_database_errors:
  File "/usr/local/lib/python3.10/site-packages/django/db/utils.py", line 90, in __exit__
    raise dj_exc_value.with_traceback(traceback) from exc_value
  File "/usr/local/lib/python3.10/site-packages/django/db/backends/utils.py", line 84, in _execute
    return self.cursor.execute(sql, params)
django.db.utils.ProgrammingError: column profiles_profile.is_opponent does not exist
LINE 1: ...le"."num_reviews", "profiles_profile"."about_me", "profiles_...
                                                             ^

2022-03-11 17:58:05,645 django.request ERROR    Internal Server Error: /admin/profiles/profile/
Traceback (most recent call last):
  File "/usr/local/lib/python3.10/site-packages/django/db/backends/utils.py", line 84, in _execute
    return self.cursor.execute(sql, params)
psycopg2.errors.UndefinedColumn: column profiles_profile.is_opponent does not exist
LINE 1: ...le"."num_reviews", "profiles_profile"."about_me", "profiles_...
                                                             ^


The above exception was the direct cause of the following exception:

Traceback (most recent call last):
  File "/usr/local/lib/python3.10/site-packages/django/core/handlers/exception.py", line 47, in inner
    response = get_response(request)
  File "/usr/local/lib/python3.10/site-packages/django/core/handlers/base.py", line 181, in _get_response
    response = wrapped_callback(request, *callback_args, **callback_kwargs)
  File "/usr/local/lib/python3.10/site-packages/django/contrib/admin/options.py", line 616, in wrapper
    return self.admin_site.admin_view(view)(*args, **kwargs)
  File "/usr/local/lib/python3.10/site-packages/django/utils/decorators.py", line 130, in _wrapped_view
    response = view_func(request, *args, **kwargs)
  File "/usr/local/lib/python3.10/site-packages/django/views/decorators/cache.py", line 44, in _wrapped_view_func
    response = view_func(request, *args, **kwargs)
  File "/usr/local/lib/python3.10/site-packages/django/contrib/admin/sites.py", line 232, in inner
    return view(request, *args, **kwargs)
  File "/usr/local/lib/python3.10/site-packages/django/utils/decorators.py", line 43, in _wrapper
    return bound_method(*args, **kwargs)
  File "/usr/local/lib/python3.10/site-packages/django/utils/decorators.py", line 130, in _wrapped_view
    response = view_func(request, *args, **kwargs)
  File "/usr/local/lib/python3.10/site-packages/django/contrib/admin/options.py", line 1815, in changelist_view
    'selection_note': _('0 of %(cnt)s selected') % {'cnt': len(cl.result_list)},
  File "/usr/local/lib/python3.10/site-packages/django/db/models/query.py", line 262, in __len__
    self._fetch_all()
  File "/usr/local/lib/python3.10/site-packages/django/db/models/query.py", line 1324, in _fetch_all
    self._result_cache = list(self._iterable_class(self))
  File "/usr/local/lib/python3.10/site-packages/django/db/models/query.py", line 51, in __iter__
    results = compiler.execute_sql(chunked_fetch=self.chunked_fetch, chunk_size=self.chunk_size)
  File "/usr/local/lib/python3.10/site-packages/django/db/models/sql/compiler.py", line 1175, in execute_sql
    cursor.execute(sql, params)
  File "/usr/local/lib/python3.10/site-packages/django/db/backends/utils.py", line 98, in execute
    return super().execute(sql, params)
  File "/usr/local/lib/python3.10/site-packages/django/db/backends/utils.py", line 66, in execute
    return self._execute_with_wrappers(sql, params, many=False, executor=self._execute)
  File "/usr/local/lib/python3.10/site-packages/django/db/backends/utils.py", line 75, in _execute_with_wrappers
    return executor(sql, params, many, context)
  File "/usr/local/lib/python3.10/site-packages/django/db/backends/utils.py", line 79, in _execute
    with self.db.wrap_database_errors:
  File "/usr/local/lib/python3.10/site-packages/django/db/utils.py", line 90, in __exit__
    raise dj_exc_value.with_traceback(traceback) from exc_value
  File "/usr/local/lib/python3.10/site-packages/django/db/backends/utils.py", line 84, in _execute
    return self.cursor.execute(sql, params)
django.db.utils.ProgrammingError: column profiles_profile.is_opponent does not exist
LINE 1: ...le"."num_reviews", "profiles_profile"."about_me", "profiles_...
                                                             ^

2022-03-11 17:58:11,476 django.request ERROR    Internal Server Error: /admin/profiles/profile/
Traceback (most recent call last):
  File "/usr/local/lib/python3.10/site-packages/django/db/backends/utils.py", line 84, in _execute
    return self.cursor.execute(sql, params)
psycopg2.errors.UndefinedColumn: column profiles_profile.is_opponent does not exist
LINE 1: ...le"."num_reviews", "profiles_profile"."about_me", "profiles_...
                                                             ^


The above exception was the direct cause of the following exception:

Traceback (most recent call last):
  File "/usr/local/lib/python3.10/site-packages/django/core/handlers/exception.py", line 47, in inner
    response = get_response(request)
  File "/usr/local/lib/python3.10/site-packages/django/core/handlers/base.py", line 181, in _get_response
    response = wrapped_callback(request, *callback_args, **callback_kwargs)
  File "/usr/local/lib/python3.10/site-packages/django/contrib/admin/options.py", line 616, in wrapper
    return self.admin_site.admin_view(view)(*args, **kwargs)
  File "/usr/local/lib/python3.10/site-packages/django/utils/decorators.py", line 130, in _wrapped_view
    response = view_func(request, *args, **kwargs)
  File "/usr/local/lib/python3.10/site-packages/django/views/decorators/cache.py", line 44, in _wrapped_view_func
    response = view_func(request, *args, **kwargs)
  File "/usr/local/lib/python3.10/site-packages/django/contrib/admin/sites.py", line 232, in inner
    return view(request, *args, **kwargs)
  File "/usr/local/lib/python3.10/site-packages/django/utils/decorators.py", line 43, in _wrapper
    return bound_method(*args, **kwargs)
  File "/usr/local/lib/python3.10/site-packages/django/utils/decorators.py", line 130, in _wrapped_view
    response = view_func(request, *args, **kwargs)
  File "/usr/local/lib/python3.10/site-packages/django/contrib/admin/options.py", line 1815, in changelist_view
    'selection_note': _('0 of %(cnt)s selected') % {'cnt': len(cl.result_list)},
  File "/usr/local/lib/python3.10/site-packages/django/db/models/query.py", line 262, in __len__
    self._fetch_all()
  File "/usr/local/lib/python3.10/site-packages/django/db/models/query.py", line 1324, in _fetch_all
    self._result_cache = list(self._iterable_class(self))
  File "/usr/local/lib/python3.10/site-packages/django/db/models/query.py", line 51, in __iter__
    results = compiler.execute_sql(chunked_fetch=self.chunked_fetch, chunk_size=self.chunk_size)
  File "/usr/local/lib/python3.10/site-packages/django/db/models/sql/compiler.py", line 1175, in execute_sql
    cursor.execute(sql, params)
  File "/usr/local/lib/python3.10/site-packages/django/db/backends/utils.py", line 98, in execute
    return super().execute(sql, params)
  File "/usr/local/lib/python3.10/site-packages/django/db/backends/utils.py", line 66, in execute
    return self._execute_with_wrappers(sql, params, many=False, executor=self._execute)
  File "/usr/local/lib/python3.10/site-packages/django/db/backends/utils.py", line 75, in _execute_with_wrappers
    return executor(sql, params, many, context)
  File "/usr/local/lib/python3.10/site-packages/django/db/backends/utils.py", line 79, in _execute
    with self.db.wrap_database_errors:
  File "/usr/local/lib/python3.10/site-packages/django/db/utils.py", line 90, in __exit__
    raise dj_exc_value.with_traceback(traceback) from exc_value
  File "/usr/local/lib/python3.10/site-packages/django/db/backends/utils.py", line 84, in _execute
    return self.cursor.execute(sql, params)
django.db.utils.ProgrammingError: column profiles_profile.is_opponent does not exist
LINE 1: ...le"."num_reviews", "profiles_profile"."about_me", "profiles_...
                                                             ^

2022-03-11 17:58:55,774 django.request ERROR    Internal Server Error: /admin/profiles/profile/
Traceback (most recent call last):
  File "/usr/local/lib/python3.10/site-packages/django/db/backends/utils.py", line 84, in _execute
    return self.cursor.execute(sql, params)
psycopg2.errors.UndefinedColumn: column profiles_profile.is_opponent does not exist
LINE 1: ...le"."num_reviews", "profiles_profile"."about_me", "profiles_...
                                                             ^


The above exception was the direct cause of the following exception:

Traceback (most recent call last):
  File "/usr/local/lib/python3.10/site-packages/django/core/handlers/exception.py", line 47, in inner
    response = get_response(request)
  File "/usr/local/lib/python3.10/site-packages/django/core/handlers/base.py", line 181, in _get_response
    response = wrapped_callback(request, *callback_args, **callback_kwargs)
  File "/usr/local/lib/python3.10/site-packages/django/contrib/admin/options.py", line 616, in wrapper
    return self.admin_site.admin_view(view)(*args, **kwargs)
  File "/usr/local/lib/python3.10/site-packages/django/utils/decorators.py", line 130, in _wrapped_view
    response = view_func(request, *args, **kwargs)
  File "/usr/local/lib/python3.10/site-packages/django/views/decorators/cache.py", line 44, in _wrapped_view_func
    response = view_func(request, *args, **kwargs)
  File "/usr/local/lib/python3.10/site-packages/django/contrib/admin/sites.py", line 232, in inner
    return view(request, *args, **kwargs)
  File "/usr/local/lib/python3.10/site-packages/django/utils/decorators.py", line 43, in _wrapper
    return bound_method(*args, **kwargs)
  File "/usr/local/lib/python3.10/site-packages/django/utils/decorators.py", line 130, in _wrapped_view
    response = view_func(request, *args, **kwargs)
  File "/usr/local/lib/python3.10/site-packages/django/contrib/admin/options.py", line 1815, in changelist_view
    'selection_note': _('0 of %(cnt)s selected') % {'cnt': len(cl.result_list)},
  File "/usr/local/lib/python3.10/site-packages/django/db/models/query.py", line 262, in __len__
    self._fetch_all()
  File "/usr/local/lib/python3.10/site-packages/django/db/models/query.py", line 1324, in _fetch_all
    self._result_cache = list(self._iterable_class(self))
  File "/usr/local/lib/python3.10/site-packages/django/db/models/query.py", line 51, in __iter__
    results = compiler.execute_sql(chunked_fetch=self.chunked_fetch, chunk_size=self.chunk_size)
  File "/usr/local/lib/python3.10/site-packages/django/db/models/sql/compiler.py", line 1175, in execute_sql
    cursor.execute(sql, params)
  File "/usr/local/lib/python3.10/site-packages/django/db/backends/utils.py", line 98, in execute
    return super().execute(sql, params)
  File "/usr/local/lib/python3.10/site-packages/django/db/backends/utils.py", line 66, in execute
    return self._execute_with_wrappers(sql, params, many=False, executor=self._execute)
  File "/usr/local/lib/python3.10/site-packages/django/db/backends/utils.py", line 75, in _execute_with_wrappers
    return executor(sql, params, many, context)
  File "/usr/local/lib/python3.10/site-packages/django/db/backends/utils.py", line 79, in _execute
    with self.db.wrap_database_errors:
  File "/usr/local/lib/python3.10/site-packages/django/db/utils.py", line 90, in __exit__
    raise dj_exc_value.with_traceback(traceback) from exc_value
  File "/usr/local/lib/python3.10/site-packages/django/db/backends/utils.py", line 84, in _execute
    return self.cursor.execute(sql, params)
django.db.utils.ProgrammingError: column profiles_profile.is_opponent does not exist
LINE 1: ...le"."num_reviews", "profiles_profile"."about_me", "profiles_...
                                                             ^

2022-03-11 18:01:05,198 django.request WARNING  Not Found: /api/v1/users/me/
2022-03-11 18:01:41,193 django.request WARNING  Unauthorized: /api/v1/profile/me/
2022-03-11 18:01:48,923 django.request ERROR    Internal Server Error: /admin/profiles/profile/
Traceback (most recent call last):
  File "/usr/local/lib/python3.10/site-packages/django/db/backends/utils.py", line 84, in _execute
    return self.cursor.execute(sql, params)
psycopg2.errors.UndefinedColumn: column profiles_profile.is_opponent does not exist
LINE 1: ...le"."num_reviews", "profiles_profile"."about_me", "profiles_...
                                                             ^


The above exception was the direct cause of the following exception:

Traceback (most recent call last):
  File "/usr/local/lib/python3.10/site-packages/django/core/handlers/exception.py", line 47, in inner
    response = get_response(request)
  File "/usr/local/lib/python3.10/site-packages/django/core/handlers/base.py", line 181, in _get_response
    response = wrapped_callback(request, *callback_args, **callback_kwargs)
  File "/usr/local/lib/python3.10/site-packages/django/contrib/admin/options.py", line 616, in wrapper
    return self.admin_site.admin_view(view)(*args, **kwargs)
  File "/usr/local/lib/python3.10/site-packages/django/utils/decorators.py", line 130, in _wrapped_view
    response = view_func(request, *args, **kwargs)
  File "/usr/local/lib/python3.10/site-packages/django/views/decorators/cache.py", line 44, in _wrapped_view_func
    response = view_func(request, *args, **kwargs)
  File "/usr/local/lib/python3.10/site-packages/django/contrib/admin/sites.py", line 232, in inner
    return view(request, *args, **kwargs)
  File "/usr/local/lib/python3.10/site-packages/django/utils/decorators.py", line 43, in _wrapper
    return bound_method(*args, **kwargs)
  File "/usr/local/lib/python3.10/site-packages/django/utils/decorators.py", line 130, in _wrapped_view
    response = view_func(request, *args, **kwargs)
  File "/usr/local/lib/python3.10/site-packages/django/contrib/admin/options.py", line 1815, in changelist_view
    'selection_note': _('0 of %(cnt)s selected') % {'cnt': len(cl.result_list)},
  File "/usr/local/lib/python3.10/site-packages/django/db/models/query.py", line 262, in __len__
    self._fetch_all()
  File "/usr/local/lib/python3.10/site-packages/django/db/models/query.py", line 1324, in _fetch_all
    self._result_cache = list(self._iterable_class(self))
  File "/usr/local/lib/python3.10/site-packages/django/db/models/query.py", line 51, in __iter__
    results = compiler.execute_sql(chunked_fetch=self.chunked_fetch, chunk_size=self.chunk_size)
  File "/usr/local/lib/python3.10/site-packages/django/db/models/sql/compiler.py", line 1175, in execute_sql
    cursor.execute(sql, params)
  File "/usr/local/lib/python3.10/site-packages/django/db/backends/utils.py", line 98, in execute
    return super().execute(sql, params)
  File "/usr/local/lib/python3.10/site-packages/django/db/backends/utils.py", line 66, in execute
    return self._execute_with_wrappers(sql, params, many=False, executor=self._execute)
  File "/usr/local/lib/python3.10/site-packages/django/db/backends/utils.py", line 75, in _execute_with_wrappers
    return executor(sql, params, many, context)
  File "/usr/local/lib/python3.10/site-packages/django/db/backends/utils.py", line 79, in _execute
    with self.db.wrap_database_errors:
  File "/usr/local/lib/python3.10/site-packages/django/db/utils.py", line 90, in __exit__
    raise dj_exc_value.with_traceback(traceback) from exc_value
  File "/usr/local/lib/python3.10/site-packages/django/db/backends/utils.py", line 84, in _execute
    return self.cursor.execute(sql, params)
django.db.utils.ProgrammingError: column profiles_profile.is_opponent does not exist
LINE 1: ...le"."num_reviews", "profiles_profile"."about_me", "profiles_...
                                                             ^

2022-03-11 18:02:16,756 django.request WARNING  Not Found: /api/v1/users/me/
2022-03-11 18:02:26,810 django.request ERROR    Internal Server Error: /api/v1/profile/me/
Traceback (most recent call last):
  File "/usr/local/lib/python3.10/site-packages/django/db/backends/utils.py", line 84, in _execute
    return self.cursor.execute(sql, params)
psycopg2.errors.UndefinedColumn: column profiles_profile.is_opponent does not exist
LINE 1: ...le"."num_reviews", "profiles_profile"."about_me", "profiles_...
                                                             ^


The above exception was the direct cause of the following exception:

Traceback (most recent call last):
  File "/usr/local/lib/python3.10/site-packages/django/core/handlers/exception.py", line 47, in inner
    response = get_response(request)
  File "/usr/local/lib/python3.10/site-packages/django/core/handlers/base.py", line 181, in _get_response
    response = wrapped_callback(request, *callback_args, **callback_kwargs)
  File "/usr/local/lib/python3.10/site-packages/django/views/decorators/csrf.py", line 54, in wrapped_view
    return view_func(*args, **kwargs)
  File "/usr/local/lib/python3.10/site-packages/django/views/generic/base.py", line 70, in view
    return self.dispatch(request, *args, **kwargs)
  File "/usr/local/lib/python3.10/site-packages/rest_framework/views.py", line 509, in dispatch
    response = self.handle_exception(exc)
  File "/usr/local/lib/python3.10/site-packages/rest_framework/views.py", line 469, in handle_exception
    self.raise_uncaught_exception(exc)
  File "/usr/local/lib/python3.10/site-packages/rest_framework/views.py", line 480, in raise_uncaught_exception
    raise exc
  File "/usr/local/lib/python3.10/site-packages/rest_framework/views.py", line 506, in dispatch
    response = handler(request, *args, **kwargs)
  File "/app/apps/profiles/views.py", line 37, in get
    user_profile = Profile.objects.get(user=user)
  File "/usr/local/lib/python3.10/site-packages/django/db/models/manager.py", line 85, in manager_method
    return getattr(self.get_queryset(), name)(*args, **kwargs)
  File "/usr/local/lib/python3.10/site-packages/django/db/models/query.py", line 431, in get
    num = len(clone)
  File "/usr/local/lib/python3.10/site-packages/django/db/models/query.py", line 262, in __len__
    self._fetch_all()
  File "/usr/local/lib/python3.10/site-packages/django/db/models/query.py", line 1324, in _fetch_all
    self._result_cache = list(self._iterable_class(self))
  File "/usr/local/lib/python3.10/site-packages/django/db/models/query.py", line 51, in __iter__
    results = compiler.execute_sql(chunked_fetch=self.chunked_fetch, chunk_size=self.chunk_size)
  File "/usr/local/lib/python3.10/site-packages/django/db/models/sql/compiler.py", line 1175, in execute_sql
    cursor.execute(sql, params)
  File "/usr/local/lib/python3.10/site-packages/django/db/backends/utils.py", line 98, in execute
    return super().execute(sql, params)
  File "/usr/local/lib/python3.10/site-packages/django/db/backends/utils.py", line 66, in execute
    return self._execute_with_wrappers(sql, params, many=False, executor=self._execute)
  File "/usr/local/lib/python3.10/site-packages/django/db/backends/utils.py", line 75, in _execute_with_wrappers
    return executor(sql, params, many, context)
  File "/usr/local/lib/python3.10/site-packages/django/db/backends/utils.py", line 79, in _execute
    with self.db.wrap_database_errors:
  File "/usr/local/lib/python3.10/site-packages/django/db/utils.py", line 90, in __exit__
    raise dj_exc_value.with_traceback(traceback) from exc_value
  File "/usr/local/lib/python3.10/site-packages/django/db/backends/utils.py", line 84, in _execute
    return self.cursor.execute(sql, params)
django.db.utils.ProgrammingError: column profiles_profile.is_opponent does not exist
LINE 1: ...le"."num_reviews", "profiles_profile"."about_me", "profiles_...
                                                             ^

2022-03-11 18:03:03,423 django.request WARNING  Unauthorized: /api/v1/profile/opponents/all/
2022-03-11 18:03:09,021 django.request ERROR    Internal Server Error: /api/v1/profile/opponents/all/
Traceback (most recent call last):
  File "/usr/local/lib/python3.10/site-packages/django/db/backends/utils.py", line 84, in _execute
    return self.cursor.execute(sql, params)
psycopg2.errors.UndefinedColumn: column profiles_profile.is_opponent does not exist
LINE 1: ...le"."num_reviews", "profiles_profile"."about_me", "profiles_...
                                                             ^


The above exception was the direct cause of the following exception:

Traceback (most recent call last):
  File "/usr/local/lib/python3.10/site-packages/django/core/handlers/exception.py", line 47, in inner
    response = get_response(request)
  File "/usr/local/lib/python3.10/site-packages/django/core/handlers/base.py", line 181, in _get_response
    response = wrapped_callback(request, *callback_args, **callback_kwargs)
  File "/usr/local/lib/python3.10/site-packages/django/views/decorators/csrf.py", line 54, in wrapped_view
    return view_func(*args, **kwargs)
  File "/usr/local/lib/python3.10/site-packages/django/views/generic/base.py", line 70, in view
    return self.dispatch(request, *args, **kwargs)
  File "/usr/local/lib/python3.10/site-packages/rest_framework/views.py", line 509, in dispatch
    response = self.handle_exception(exc)
  File "/usr/local/lib/python3.10/site-packages/rest_framework/views.py", line 469, in handle_exception
    self.raise_uncaught_exception(exc)
  File "/usr/local/lib/python3.10/site-packages/rest_framework/views.py", line 480, in raise_uncaught_exception
    raise exc
  File "/usr/local/lib/python3.10/site-packages/rest_framework/views.py", line 506, in dispatch
    response = handler(request, *args, **kwargs)
  File "/usr/local/lib/python3.10/site-packages/rest_framework/generics.py", line 199, in get
    return self.list(request, *args, **kwargs)
  File "/usr/local/lib/python3.10/site-packages/rest_framework/mixins.py", line 46, in list
    return Response(serializer.data)
  File "/usr/local/lib/python3.10/site-packages/rest_framework/serializers.py", line 745, in data
    ret = super().data
  File "/usr/local/lib/python3.10/site-packages/rest_framework/serializers.py", line 246, in data
    self._data = self.to_representation(self.instance)
  File "/usr/local/lib/python3.10/site-packages/rest_framework/serializers.py", line 663, in to_representation
    return [
  File "/usr/local/lib/python3.10/site-packages/django/db/models/query.py", line 280, in __iter__
    self._fetch_all()
  File "/usr/local/lib/python3.10/site-packages/django/db/models/query.py", line 1324, in _fetch_all
    self._result_cache = list(self._iterable_class(self))
  File "/usr/local/lib/python3.10/site-packages/django/db/models/query.py", line 51, in __iter__
    results = compiler.execute_sql(chunked_fetch=self.chunked_fetch, chunk_size=self.chunk_size)
  File "/usr/local/lib/python3.10/site-packages/django/db/models/sql/compiler.py", line 1175, in execute_sql
    cursor.execute(sql, params)
  File "/usr/local/lib/python3.10/site-packages/django/db/backends/utils.py", line 98, in execute
    return super().execute(sql, params)
  File "/usr/local/lib/python3.10/site-packages/django/db/backends/utils.py", line 66, in execute
    return self._execute_with_wrappers(sql, params, many=False, executor=self._execute)
  File "/usr/local/lib/python3.10/site-packages/django/db/backends/utils.py", line 75, in _execute_with_wrappers
    return executor(sql, params, many, context)
  File "/usr/local/lib/python3.10/site-packages/django/db/backends/utils.py", line 79, in _execute
    with self.db.wrap_database_errors:
  File "/usr/local/lib/python3.10/site-packages/django/db/utils.py", line 90, in __exit__
    raise dj_exc_value.with_traceback(traceback) from exc_value
  File "/usr/local/lib/python3.10/site-packages/django/db/backends/utils.py", line 84, in _execute
    return self.cursor.execute(sql, params)
django.db.utils.ProgrammingError: column profiles_profile.is_opponent does not exist
LINE 1: ...le"."num_reviews", "profiles_profile"."about_me", "profiles_...
                                                             ^

2022-03-11 18:08:27,181 django.utils.autoreload INFO     Watching for file changes with StatReloader
2022-03-11 18:10:00,197 django.request WARNING  Bad Request: /api/v1/auth/users/activation/
2022-03-11 18:10:17,023 django.request WARNING  Bad Request: /api/v1/auth/users/activation/
2022-03-11 18:10:26,759 django.request WARNING  Not Found: /activate/NA/b24t1s-fc423e8d34025fe3757bbf90c5cd1e00
2022-03-11 18:10:30,934 django.request WARNING  Bad Request: /api/v1/auth/users/activation/
2022-03-11 18:10:31,874 django.request WARNING  Bad Request: /api/v1/auth/users/activation/
2022-03-11 18:10:32,564 django.request WARNING  Bad Request: /api/v1/auth/users/activation/
2022-03-11 18:10:57,193 django.request WARNING  Bad Request: /api/v1/auth/users/activation/
2022-03-11 18:11:16,567 django.request WARNING  Not Found: /activate/NA/b24t1s-fc423e8d34025fe3757bbf90c5cd1e00
2022-03-11 18:11:34,740 django.request WARNING  Bad Request: /api/v1/auth/users/activation/
2022-03-11 18:14:30,186 django.request ERROR    Internal Server Error: /api/v1/ratings/88850316-e3dd-4a5b-a4e1-3e5c1522e393/
Traceback (most recent call last):
  File "/usr/local/lib/python3.10/site-packages/django/core/handlers/exception.py", line 47, in inner
    response = get_response(request)
  File "/usr/local/lib/python3.10/site-packages/django/core/handlers/base.py", line 181, in _get_response
    response = wrapped_callback(request, *callback_args, **callback_kwargs)
  File "/usr/local/lib/python3.10/site-packages/django/views/decorators/csrf.py", line 54, in wrapped_view
    return view_func(*args, **kwargs)
  File "/usr/local/lib/python3.10/site-packages/django/views/generic/base.py", line 70, in view
    return self.dispatch(request, *args, **kwargs)
  File "/usr/local/lib/python3.10/site-packages/rest_framework/views.py", line 509, in dispatch
    response = self.handle_exception(exc)
  File "/usr/local/lib/python3.10/site-packages/rest_framework/views.py", line 469, in handle_exception
    self.raise_uncaught_exception(exc)
  File "/usr/local/lib/python3.10/site-packages/rest_framework/views.py", line 480, in raise_uncaught_exception
    raise exc
  File "/usr/local/lib/python3.10/site-packages/rest_framework/views.py", line 506, in dispatch
    response = handler(request, *args, **kwargs)
  File "/usr/local/lib/python3.10/site-packages/rest_framework/decorators.py", line 50, in handler
    return func(*args, **kwargs)
  File "/app/apps/ratings/views.py", line 16, in create_opponent_review
    opponent_profile = Profile.objects.get(id=profile_id, is_opponent=True)
  File "/usr/local/lib/python3.10/site-packages/django/db/models/manager.py", line 85, in manager_method
    return getattr(self.get_queryset(), name)(*args, **kwargs)
  File "/usr/local/lib/python3.10/site-packages/django/db/models/query.py", line 435, in get
    raise self.model.DoesNotExist(
apps.profiles.models.Profile.DoesNotExist: Profile matching query does not exist.
2022-03-11 18:14:43,701 django.request WARNING  Unauthorized: /api/v1/profile/me/
2022-03-11 18:17:18,433 django.request ERROR    Internal Server Error: /api/v1/ratings/88850316-e3dd-4a5b-a4e1-3e5c1522e393/
Traceback (most recent call last):
  File "/usr/local/lib/python3.10/site-packages/django/core/handlers/exception.py", line 47, in inner
    response = get_response(request)
  File "/usr/local/lib/python3.10/site-packages/django/core/handlers/base.py", line 181, in _get_response
    response = wrapped_callback(request, *callback_args, **callback_kwargs)
  File "/usr/local/lib/python3.10/site-packages/django/views/decorators/csrf.py", line 54, in wrapped_view
    return view_func(*args, **kwargs)
  File "/usr/local/lib/python3.10/site-packages/django/views/generic/base.py", line 70, in view
    return self.dispatch(request, *args, **kwargs)
  File "/usr/local/lib/python3.10/site-packages/rest_framework/views.py", line 509, in dispatch
    response = self.handle_exception(exc)
  File "/usr/local/lib/python3.10/site-packages/rest_framework/views.py", line 469, in handle_exception
    self.raise_uncaught_exception(exc)
  File "/usr/local/lib/python3.10/site-packages/rest_framework/views.py", line 480, in raise_uncaught_exception
    raise exc
  File "/usr/local/lib/python3.10/site-packages/rest_framework/views.py", line 506, in dispatch
    response = handler(request, *args, **kwargs)
  File "/usr/local/lib/python3.10/site-packages/rest_framework/decorators.py", line 50, in handler
    return func(*args, **kwargs)
  File "/app/apps/ratings/views.py", line 16, in create_opponent_review
    opponent_profile = Profile.objects.get(id=profile_id, is_opponent=True)
  File "/usr/local/lib/python3.10/site-packages/django/db/models/manager.py", line 85, in manager_method
    return getattr(self.get_queryset(), name)(*args, **kwargs)
  File "/usr/local/lib/python3.10/site-packages/django/db/models/query.py", line 435, in get
    raise self.model.DoesNotExist(
apps.profiles.models.Profile.DoesNotExist: Profile matching query does not exist.
2022-03-11 18:17:37,608 django.request ERROR    Internal Server Error: /api/v1/ratings/c6565aff-2ff4-45fe-bc51-e0ff5554339a/
Traceback (most recent call last):
  File "/usr/local/lib/python3.10/site-packages/django/core/handlers/exception.py", line 47, in inner
    response = get_response(request)
  File "/usr/local/lib/python3.10/site-packages/django/core/handlers/base.py", line 181, in _get_response
    response = wrapped_callback(request, *callback_args, **callback_kwargs)
  File "/usr/local/lib/python3.10/site-packages/django/views/decorators/csrf.py", line 54, in wrapped_view
    return view_func(*args, **kwargs)
  File "/usr/local/lib/python3.10/site-packages/django/views/generic/base.py", line 70, in view
    return self.dispatch(request, *args, **kwargs)
  File "/usr/local/lib/python3.10/site-packages/rest_framework/views.py", line 509, in dispatch
    response = self.handle_exception(exc)
  File "/usr/local/lib/python3.10/site-packages/rest_framework/views.py", line 469, in handle_exception
    self.raise_uncaught_exception(exc)
  File "/usr/local/lib/python3.10/site-packages/rest_framework/views.py", line 480, in raise_uncaught_exception
    raise exc
  File "/usr/local/lib/python3.10/site-packages/rest_framework/views.py", line 506, in dispatch
    response = handler(request, *args, **kwargs)
  File "/usr/local/lib/python3.10/site-packages/rest_framework/decorators.py", line 50, in handler
    return func(*args, **kwargs)
  File "/app/apps/ratings/views.py", line 16, in create_opponent_review
    opponent_profile = Profile.objects.get(id=profile_id, is_opponent=True)
  File "/usr/local/lib/python3.10/site-packages/django/db/models/manager.py", line 85, in manager_method
    return getattr(self.get_queryset(), name)(*args, **kwargs)
  File "/usr/local/lib/python3.10/site-packages/django/db/models/query.py", line 435, in get
    raise self.model.DoesNotExist(
apps.profiles.models.Profile.DoesNotExist: Profile matching query does not exist.
2022-03-11 18:18:50,932 django.request ERROR    Internal Server Error: /api/v1/ratings/0493693a-b154-4458-a61c-1be4d80e9d25/
Traceback (most recent call last):
  File "/usr/local/lib/python3.10/site-packages/django/core/handlers/exception.py", line 47, in inner
    response = get_response(request)
  File "/usr/local/lib/python3.10/site-packages/django/core/handlers/base.py", line 181, in _get_response
    response = wrapped_callback(request, *callback_args, **callback_kwargs)
  File "/usr/local/lib/python3.10/site-packages/django/views/decorators/csrf.py", line 54, in wrapped_view
    return view_func(*args, **kwargs)
  File "/usr/local/lib/python3.10/site-packages/django/views/generic/base.py", line 70, in view
    return self.dispatch(request, *args, **kwargs)
  File "/usr/local/lib/python3.10/site-packages/rest_framework/views.py", line 509, in dispatch
    response = self.handle_exception(exc)
  File "/usr/local/lib/python3.10/site-packages/rest_framework/views.py", line 469, in handle_exception
    self.raise_uncaught_exception(exc)
  File "/usr/local/lib/python3.10/site-packages/rest_framework/views.py", line 480, in raise_uncaught_exception
    raise exc
  File "/usr/local/lib/python3.10/site-packages/rest_framework/views.py", line 506, in dispatch
    response = handler(request, *args, **kwargs)
  File "/usr/local/lib/python3.10/site-packages/rest_framework/decorators.py", line 50, in handler
    return func(*args, **kwargs)
  File "/app/apps/ratings/views.py", line 32, in create_opponent_review
    elif data["rating"] == 0:
KeyError: 'rating'
2022-03-11 18:25:00,008 django.utils.autoreload INFO     /app/apps/profiles/models.py changed, reloading.
2022-03-11 18:25:01,597 django.utils.autoreload INFO     Watching for file changes with StatReloader
2022-03-11 18:25:05,299 django.utils.autoreload INFO     /app/apps/profiles/models.py changed, reloading.
2022-03-11 18:25:06,777 django.utils.autoreload INFO     Watching for file changes with StatReloader
